Workbook

Sheet Cover
A16: TIMES-Ireland Model
A19: Document type: | B19: Base Year Template
A20: Sector(s): | B20: Industry sector (IND)
A21: Purpose: | B21: Specify base year data and define sector structure
A23: Original developer(s): | B23: Olexandr Balyk (UCC, olexandr.balyk@ucc.ie)
B24: Bakytzhan Suleimenov (UCC, bsuleimenov@ucc.ie)
A26: Current maintainer(s): | B26: Bakytzhan Suleimenov (UCC, bsuleimenov@ucc.ie)
A29: Part of TIM version: | B29: 1
A30: Model repository: | B30: https://github.com/MaREI-EPMG/TIMES-Ireland-model
A31: Licence: | B31: CC BY-NC-SA 4.0 (unless specified otherwise)
B32: https://creativecommons.org/licenses/by-nc-sa/4.0/

Sheet Regions
C3: {=INDEX(C5:C7,$A$4)} -> IE | D3: {=INDEX(D5:D7,$A$4)} -> National | E3: {=INDEX(E5:E7,$A$4)} -> IE-CW | F3: {=INDEX(F5:F7,$A$4)} -> IE-D | G3: {=INDEX(G5:G7,$A$4)} -> IE-KE | H3: {=INDEX(H5:H7,$A$4)} -> IE-KK | I3: {=INDEX(I5:I7,$A$4)} -> IE-LS | J3: {=INDEX(J5:J7,$A$4)} -> IE-LD | ... AD3: {=INDEX(AD5:AD7,$A$4)} -> IE-MN
A4: 1
A5: Development | C5: IE | D5: National | E5: =A11 -> IE-CW | F5: =A16 -> IE-D | G5: =A19 -> IE-KE | H5: =A20 -> IE-KK | I5: =A21 -> IE-LS | J5: =A24 -> IE-LD | K5: =A25 -> IE-LH | L5: =A27 -> IE-MH | M5: =A29 -> IE-OY | N5: =A34 -> IE-WH | O5: =A35 -> IE-WX | P5: =A36 -> IE-WW | Q5: =A13 -> IE-CE | R5: =A14 -> IE-CO | S5: =A18 -> IE-KY | T5: =A23 -> IE-LK | U5: =A32 -> IE-TA | V5: =A33 -> IE-WD | W5: =A17 -> IE-G | X5: =A22 -> IE-LM | Y5: =A26 -> IE-MO | Z5: =A30 -> IE-RN | AA5: =A31 -> IE-SO | AB5: =A12 -> IE-CN | AC5: =A15 -> IE-DL | AD5: =A28 -> IE-MN
A6: Single-region | C6: =C5 -> IE | D6: ="*"&D5 -> *National | E6: ="*"&E5 -> *IE-CW | F6: ="*"&F5 -> *IE-D | G6: ="*"&G5 -> *IE-KE | H6: ="*"&H5 -> *IE-KK | I6: ="*"&I5 -> *IE-LS | J6: ="*"&J5 -> *IE-LD | K6: ="*"&K5 -> *IE-LH | ... AD6: ="*"&AD5 -> *IE-MN
A7: Multi-region | C7: ="*"&C5 -> *IE | D7: =D5 -> National | E7: =E5 -> IE-CW | F7: =F5 -> IE-D | G7: =G5 -> IE-KE | H7: =H5 -> IE-KK | I7: =I5 -> IE-LS | J7: =J5 -> IE-LD | K7: =K5 -> IE-LH | ... AD7: =AD5 -> IE-MN
A10: Code | B10: County name
A11: IE-CW | B11: Carlow
A12: IE-CN | B12: Cavan
A13: IE-CE | B13: Clare
A14: IE-CO | B14: Cork
A15: IE-DL | B15: Donegal
A16: IE-D | B16: Dublin
A17: IE-G | B17: Galway
A18: IE-KY | B18: Kerry
A19: IE-KE | B19: Kildare
A20: IE-KK | B20: Kilkenny
A21: IE-LS | B21: Laois
... A36: IE-WW | B36: Wicklow
A37: Source: https://en.wikipedia.org/wiki/ISO_3166-2:IE

Sheet Commodities
B2: ~FI_Comm
B3: Csets | C3: Region | D3: CommName | E3: CommDesc | F3: Unit | G3: LimType | H3: CTSLvl | I3: PeakTS | J3: Ctype
B4: \I: Energy commodities
B5: NRG | C5: =_xlfn.TEXTJOIN(",",TRUE,IF(LEFT(Regions!$C$3,1)<>"*",Regions!$C$3,""),IF(LEFT(Regions!$D$3,1)<>"*",Regions!$D$3,"")) -> IE,National | D5: INDCOA | E5: Coal (IND) | F5: PJ | G5: FX
B6: \I: | C6: =_xlfn.TEXTJOIN(",",TRUE,IF(LEFT(Regions!$C$3,1)<>"*",Regions!$C$3,""),IF(LEFT(Regions!$D$3,1)<>"*",Regions!$D$3,"")) -> IE,National | D6: INDPEA | E6: Peat (IND) | F6: PJ | G6: FX
B7: NRG | C7: =_xlfn.TEXTJOIN(",",TRUE,IF(LEFT(Regions!$C$3,1)<>"*",Regions!$C$3,""),IF(LEFT(Regions!$D$3,1)<>"*",Regions!$D$3,"")) -> IE,National | D7: INDOIL | E7: Oil products (IND) | F7: PJ | G7: FX
B8: NRG | C8: =_xlfn.TEXTJOIN(",",TRUE,IF(LEFT(Regions!$C$3,1)<>"*",Regions!$C$3,""),IF(LEFT(Regions!$D$3,1)<>"*",Regions!$D$3,"")) -> IE,National | D8: INDBKE | E8: BioKerosene (IND) | F8: PJ | G8: FX
B9: \I: | C9: =_xlfn.TEXTJOIN(",",TRUE,IF(LEFT(Regions!$C$3,1)<>"*",Regions!$C$3,""),IF(LEFT(Regions!$D$3,1)<>"*",Regions!$D$3,"")) -> IE,National | D9: INDHFO | E9: Heavy Fuel Oil (IND) | F9: PJ | G9: FX
B10: \I: | C10: =_xlfn.TEXTJOIN(",",TRUE,IF(LEFT(Regions!$C$3,1)<>"*",Regions!$C$3,""),IF(LEFT(Regions!$D$3,1)<>"*",Regions!$D$3,"")) -> IE,National | D10: INDLPG | E10: Liquified Petroleum Gas (IND) | F10: PJ | G10: FX
B11: \I: | C11: =_xlfn.TEXTJOIN(",",TRUE,IF(LEFT(Regions!$C$3,1)<>"*",Regions!$C$3,""),IF(LEFT(Regions!$D$3,1)<>"*",Regions!$D$3,"")) -> IE,National | D11: INDDST | E11: Diesel (IND) | F11: PJ | G11: FX
B12: NRG | C12: =_xlfn.TEXTJOIN(",",TRUE,IF(LEFT(Regions!$C$3,1)<>"*",Regions!$C$3,""),IF(LEFT(Regions!$D$3,1)<>"*",Regions!$D$3,"")) -> IE,National | D12: INDWOO | E12: Solid biomass (IND) | F12: PJ | G12: FX
B13: NRG | C13: =_xlfn.TEXTJOIN(",",TRUE,IF(LEFT(Regions!$C$3,1)<>"*",Regions!$C$3,""),IF(LEFT(Regions!$D$3,1)<>"*",Regions!$D$3,"")) -> IE,National | D13: INDCOK | E13: Petroleum Coke (IND) | F13: PJ | G13: FX
B14: NRG | C14: =_xlfn.TEXTJOIN(",",TRUE,IF(LEFT(Regions!$C$3,1)<>"*",Regions!$C$3,""),IF(LEFT(Regions!$D$3,1)<>"*",Regions!$D$3,"")) -> IE,National | D14: INDGAS | E14: Natural Gas (IND) | F14: PJ | G14: FX
B15: \I: | C15: =_xlfn.TEXTJOIN(",",TRUE,IF(LEFT(Regions!$C$3,1)<>"*",Regions!$C$3,""),IF(LEFT(Regions!$D$3,1)<>"*",Regions!$D$3,"")) -> IE,National | D15: INDHTH | E15: High Grade Heat (>500 C) | F15: PJ | G15: FX | H15: DAYNITE | J15: HTHEAT
B16: \I: | C16: =_xlfn.TEXTJOIN(",",TRUE,IF(LEFT(Regions!$C$3,1)<>"*",Regions!$C$3,""),IF(LEFT(Regions!$D$3,1)<>"*",Regions!$D$3,"")) -> IE,National | D16: INDMTH | E16: Medium Grade Heat (150 - 500 C) | F16: PJ | G16: FX | H16: DAYNITE | J16: HTHEAT
B17: \I: | C17: =_xlfn.TEXTJOIN(",",TRUE,IF(LEFT(Regions!$C$3,1)<>"*",Regions!$C$3,""),IF(LEFT(Regions!$D$3,1)<>"*",Regions!$D$3,"")) -> IE,National | D17: INDLTH | E17: Medium/Low Grade Heat (100 - 150 C) | F17: PJ | G17: FX | H17: DAYNITE | J17: LTHEAT
B18: \I: | C18: =_xlfn.TEXTJOIN(",",TRUE,IF(LEFT(Regions!$C$3,1)<>"*",Regions!$C$3,""),IF(LEFT(Regions!$D$3,1)<>"*",Regions!$D$3,"")) -> IE,National | D18: INDHET | E18: Low Grade Heat (<100 C) | F18: PJ | G18: FX | H18: DAYNITE | J18: LTHEAT
B19: NRG | C19: =_xlfn.TEXTJOIN(",",TRUE,IF(LEFT(Regions!$C$3,1)<>"*",Regions!$C$3,""),IF(LEFT(Regions!$D$3,1)<>"*",Regions!$D$3,"")) -> IE,National | D19: INDELC | E19: Electricity (IND) | F19: PJ | G19: FX | H19: DAYNITE | J19: ELC
B20: NRG | C20: =_xlfn.TEXTJOIN(",",TRUE,IF(LEFT(Regions!$C$3,1)<>"*",Regions!$C$3,""),IF(LEFT(Regions!$D$3,1)<>"*",Regions!$D$3,"")) -> IE,National | D20: INDBGS | E20: Biogas (IND) | F20: PJ | G20: FX
B21: NRG | C21: =_xlfn.TEXTJOIN(",",TRUE,IF(LEFT(Regions!$C$3,1)<>"*",Regions!$C$3,""),IF(LEFT(Regions!$D$3,1)<>"*",Regions!$D$3,"")) -> IE,National | D21: INDBIO | E21: Biomass (IND) | F21: PJ | G21: FX
B22: NRG | C22: =_xlfn.TEXTJOIN(",",TRUE,IF(LEFT(Regions!$C$3,1)<>"*",Regions!$C$3,""),IF(LEFT(Regions!$D$3,1)<>"*",Regions!$D$3,"")) -> IE,National | D22: INDRWS | E22: Renewable waste (IND) | F22: PJ | G22: FX
B23: NRG | C23: =_xlfn.TEXTJOIN(",",TRUE,IF(LEFT(Regions!$C$3,1)<>"*",Regions!$C$3,""),IF(LEFT(Regions!$D$3,1)<>"*",Regions!$D$3,"")) -> IE,National | D23: INDNWS | E23: Non-renewable waste (IND) | F23: PJ | G23: FX
B24: NRG | C24: =_xlfn.TEXTJOIN(",",TRUE,IF(LEFT(Regions!$C$3,1)<>"*",Regions!$C$3,""),IF(LEFT(Regions!$D$3,1)<>"*",Regions!$D$3,"")) -> IE,National | D24: INDH2G | E24: Hydrogen gaseous (IND) | F24: PJ | G24: FX
B25: NRG | C25: =_xlfn.TEXTJOIN(",",TRUE,IF(LEFT(Regions!$C$3,1)<>"*",Regions!$C$3,""),IF(LEFT(Regions!$D$3,1)<>"*",Regions!$D$3,"")) -> IE,National | D25: INDH2L | E25: Hydrogen liquid (IND) | F25: PJ | G25: FX
B26: \I: Demand commodities
B27: DEM | C27: =_xlfn.TEXTJOIN(",",TRUE,IF(LEFT(Regions!$C$3,1)<>"*",Regions!$C$3,""),IF(LEFT(Regions!$D$3,1)<>"*",Regions!$D$3,"")) -> IE,National | D27: =+"I"&P27 -> ICEM | E27: Cement industry demand | F27: PJ | O27: Cement | P27: CEM
B28: DEM | C28: =_xlfn.TEXTJOIN(",",TRUE,IF(LEFT(Regions!$C$3,1)<>"*",Regions!$C$3,""),IF(LEFT(Regions!$D$3,1)<>"*",Regions!$D$3,"")) -> IE,National | D28: =+"I"&P28 -> ICAF | E28: Chemicals industry demand | F28: PJ | O28: Chemicals | P28: CAF
B29: DEM | C29: =_xlfn.TEXTJOIN(",",TRUE,IF(LEFT(Regions!$C$3,1)<>"*",Regions!$C$3,""),IF(LEFT(Regions!$D$3,1)<>"*",Regions!$D$3,"")) -> IE,National | D29: =+"I"&P29 -> IFAP | E29: =O29&" demand" -> Food and Drink demand | F29: PJ | O29: Food and Drink | P29: FAP
B30: DEM | C30: =_xlfn.TEXTJOIN(",",TRUE,IF(LEFT(Regions!$C$3,1)<>"*",Regions!$C$3,""),IF(LEFT(Regions!$D$3,1)<>"*",Regions!$D$3,"")) -> IE,National | D30: =+"I"&P30 -> ILIM | E30: =O30&" demand" -> Lime demand | F30: PJ | O30: Lime | P30: LIM
B31: DEM | C31: =_xlfn.TEXTJOIN(",",TRUE,IF(LEFT(Regions!$C$3,1)<>"*",Regions!$C$3,""),IF(LEFT(Regions!$D$3,1)<>"*",Regions!$D$3,"")) -> IE,National | D31: =+"I"&P31 -> IMAP | E31: =O31&" demand" -> Metals demand | F31: PJ | O31: Metals | P31: MAP
B32: DEM | C32: =_xlfn.TEXTJOIN(",",TRUE,IF(LEFT(Regions!$C$3,1)<>"*",Regions!$C$3,""),IF(LEFT(Regions!$D$3,1)<>"*",Regions!$D$3,"")) -> IE,National | D32: =+"I"&P32 -> IOMA | E32: =O32&" demand" -> Other Industry demand | F32: PJ | O32: Other Industry | P32: OMA
B33: DEM | C33: =_xlfn.TEXTJOIN(",",TRUE,IF(LEFT(Regions!$C$3,1)<>"*",Regions!$C$3,""),IF(LEFT(Regions!$D$3,1)<>"*",Regions!$D$3,"")) -> IE,National | D33: =+"I"&P33 -> IONM | E33: Other non-metallic minerals | F33: PJ | O33: Other Minerals | P33: ONM
B34: \I: | O34: Refining | P34: REF
B35: DEM | C35: =_xlfn.TEXTJOIN(",",TRUE,IF(LEFT(Regions!$C$3,1)<>"*",Regions!$C$3,""),IF(LEFT(Regions!$D$3,1)<>"*",Regions!$D$3,"")) -> IE,National | D35: =+"I"&P35 -> IWAP | E35: =O35&" demand" -> Wood Products demand | F35: PJ | O35: Wood Products | P35: WAP
B36: DEM | C36: =_xlfn.TEXTJOIN(",",TRUE,IF(LEFT(Regions!$C$3,1)<>"*",Regions!$C$3,""),IF(LEFT(Regions!$D$3,1)<>"*",Regions!$D$3,"")) -> IE,National | D36: IELC | E36: Electricity consumption industry | F36: PJ
B37: DEM | C37: =_xlfn.TEXTJOIN(",",TRUE,IF(LEFT(Regions!$C$3,1)<>"*",Regions!$C$3,""),IF(LEFT(Regions!$D$3,1)<>"*",Regions!$D$3,"")) -> IE,National | D37: IOIL | E37: Residual oil consumption industry | F37: PJ
B38: \I:
B39: \I:
B40: \I:
B41: \I: Emissions commodities
...

Sheet Processes
B2: ~FI_Process
B3: Sets | C3: Region | D3: TechName | E3: TechDesc | F3: Tact | G3: Tcap | H3: Tslvl | I3: PrimaryCG | J3: Vintage
B4: \I: Demand Processes
B5: DMD | C5: =_xlfn.TEXTJOIN(",",TRUE,IF(LEFT(Regions!$C$3,1)<>"*",Regions!$C$3,""),IF(LEFT(Regions!$D$3,1)<>"*",Regions!$D$3,"")) -> IE,National | D5: =_xlfn.TEXTJOIN("-",TRUE,"I",B5,MID(Commodities!D27,2,3),"E0") -> I-DMD-CEM-E0 | E5: =_xlfn.CONCAT(Commodities!E27," process") -> Cement industry demand process | F5: PJ | G5: PJa
B6: DMD | C6: =_xlfn.TEXTJOIN(",",TRUE,IF(LEFT(Regions!$C$3,1)<>"*",Regions!$C$3,""),IF(LEFT(Regions!$D$3,1)<>"*",Regions!$D$3,"")) -> IE,National | D6: =_xlfn.TEXTJOIN("-",TRUE,"I",B6,MID(Commodities!D28,2,3),"E0") -> I-DMD-CAF-E0 | E6: =_xlfn.CONCAT(Commodities!E28," process") -> Chemicals industry demand process | F6: PJ | G6: PJa
B7: DMD | C7: =_xlfn.TEXTJOIN(",",TRUE,IF(LEFT(Regions!$C$3,1)<>"*",Regions!$C$3,""),IF(LEFT(Regions!$D$3,1)<>"*",Regions!$D$3,"")) -> IE,National | D7: =_xlfn.TEXTJOIN("-",TRUE,"I",B7,MID(Commodities!D29,2,3),"E0") -> I-DMD-FAP-E0 | E7: =_xlfn.CONCAT(Commodities!E29," process") -> Food and Drink demand process | F7: PJ | G7: PJa
B8: DMD | C8: =_xlfn.TEXTJOIN(",",TRUE,IF(LEFT(Regions!$C$3,1)<>"*",Regions!$C$3,""),IF(LEFT(Regions!$D$3,1)<>"*",Regions!$D$3,"")) -> IE,National | D8: =_xlfn.TEXTJOIN("-",TRUE,"I",B8,MID(Commodities!D30,2,3),"E0") -> I-DMD-LIM-E0 | E8: =_xlfn.CONCAT(Commodities!E30," process") -> Lime demand process | F8: PJ | G8: PJa
B9: DMD | C9: =_xlfn.TEXTJOIN(",",TRUE,IF(LEFT(Regions!$C$3,1)<>"*",Regions!$C$3,""),IF(LEFT(Regions!$D$3,1)<>"*",Regions!$D$3,"")) -> IE,National | D9: =_xlfn.TEXTJOIN("-",TRUE,"I",B9,MID(Commodities!D31,2,3),"E0") -> I-DMD-MAP-E0 | E9: =_xlfn.CONCAT(Commodities!E31," process") -> Metals demand process | F9: PJ | G9: PJa
B10: DMD | C10: =_xlfn.TEXTJOIN(",",TRUE,IF(LEFT(Regions!$C$3,1)<>"*",Regions!$C$3,""),IF(LEFT(Regions!$D$3,1)<>"*",Regions!$D$3,"")) -> IE,National | D10: =_xlfn.TEXTJOIN("-",TRUE,"I",B10,MID(Commodities!D32,2,3),"E0") -> I-DMD-OMA-E0 | E10: =_xlfn.CONCAT(Commodities!E32," process") -> Other Industry demand process | F10: PJ | G10: PJa
B11: DMD | C11: =_xlfn.TEXTJOIN(",",TRUE,IF(LEFT(Regions!$C$3,1)<>"*",Regions!$C$3,""),IF(LEFT(Regions!$D$3,1)<>"*",Regions!$D$3,"")) -> IE,National | D11: =_xlfn.TEXTJOIN("-",TRUE,"I",B11,MID(Commodities!D33,2,3),"E0") -> I-DMD-ONM-E0 | E11: =_xlfn.CONCAT(Commodities!E33," process") -> Other non-metallic minerals process | F11: PJ | G11: PJa
B12: \I: | C12: =_xlfn.TEXTJOIN(",",TRUE,IF(LEFT(Regions!$C$3,1)<>"*",Regions!$C$3,""),IF(LEFT(Regions!$D$3,1)<>"*",Regions!$D$3,"")) -> IE,National | D12: =_xlfn.TEXTJOIN("-",TRUE,"I",B12,MID(Commodities!D34,2,3),"E0") -> I-\I: -E0 | E12: =_xlfn.CONCAT(Commodities!E34," process") -> process | F12: PJ | G12: PJa
B13: DMD | C13: =_xlfn.TEXTJOIN(",",TRUE,IF(LEFT(Regions!$C$3,1)<>"*",Regions!$C$3,""),IF(LEFT(Regions!$D$3,1)<>"*",Regions!$D$3,"")) -> IE,National | D13: =_xlfn.TEXTJOIN("-",TRUE,"I",B13,MID(Commodities!D35,2,3),"E0") -> I-DMD-WAP-E0 | E13: =_xlfn.CONCAT(Commodities!E35," process") -> Wood Products demand process | F13: PJ | G13: PJa
B14: DMD | C14: =_xlfn.TEXTJOIN(",",TRUE,IF(LEFT(Regions!$C$3,1)<>"*",Regions!$C$3,""),IF(LEFT(Regions!$D$3,1)<>"*",Regions!$D$3,"")) -> IE,National | D14: =_xlfn.TEXTJOIN("-",TRUE,"I",B14,MID(Commodities!D36,2,3),"E0") -> I-DMD-ELC-E0 | E14: =_xlfn.CONCAT(Commodities!E36," process") -> Electricity consumption industry process | F14: PJ | G14: PJa
B15: DMD | C15: =_xlfn.TEXTJOIN(",",TRUE,IF(LEFT(Regions!$C$3,1)<>"*",Regions!$C$3,""),IF(LEFT(Regions!$D$3,1)<>"*",Regions!$D$3,"")) -> IE,National | D15: =_xlfn.TEXTJOIN("-",TRUE,"I",B15,MID(Commodities!D37,2,3),"E0") -> I-DMD-OIL-E0 | E15: =_xlfn.CONCAT(Commodities!E37," process") -> Residual oil consumption industry process | F15: PJ | G15: PJa
B16: \I: | C16: =_xlfn.TEXTJOIN(",",TRUE,IF(LEFT(Regions!$C$3,1)<>"*",Regions!$C$3,""),IF(LEFT(Regions!$D$3,1)<>"*",Regions!$D$3,"")) -> IE,National | D16: =_xlfn.TEXTJOIN("-",TRUE,"I",B16,MID(Commodities!D38,2,3),"E0") -> I-\I: -E0 | E16: =_xlfn.CONCAT(Commodities!E38," process") -> process | F16: PJ | G16: PJa
... B18: \I: | C18: =_xlfn.TEXTJOIN(",",TRUE,IF(LEFT(Regions!$C$3,1)<>"*",Regions!$C$3,""),IF(LEFT(Regions!$D$3,1)<>"*",Regions!$D$3,"")) -> IE,National | D18: =_xlfn.TEXTJOIN("-",TRUE,"I",B18,MID(Commodities!D40,2,3),"E0") -> I-\I: -E0 | E18: =_xlfn.CONCAT(Commodities!E40," process") -> process | F18: PJ | G18: PJa
B19: \I: Fuel Technologies
B20: PRE | C20: =_xlfn.TEXTJOIN(",",TRUE,IF(LEFT(Regions!$C$3,1)<>"*",Regions!$C$3,""),IF(LEFT(Regions!$D$3,1)<>"*",Regions!$D$3,"")) -> IE,National | D20: =_xlfn.TEXTJOIN("-",TRUE,"FT",Commodities!D5) -> FT-INDCOA | E20: =_xlfn.TEXTJOIN(" - ",TRUE,"Fuel Tech",Commodities!E5) -> Fuel Tech - Coal (IND) | F20: PJ | G20: PJa
B21: \I: | C21: =_xlfn.TEXTJOIN(",",TRUE,IF(LEFT(Regions!$C$3,1)<>"*",Regions!$C$3,""),IF(LEFT(Regions!$D$3,1)<>"*",Regions!$D$3,"")) -> IE,National | D21: =_xlfn.TEXTJOIN("-",TRUE,"FT",Commodities!D6) -> FT-INDPEA | E21: =_xlfn.TEXTJOIN(" - ",TRUE,"Fuel Tech",Commodities!E6) -> Fuel Tech - Peat (IND) | F21: PJ | G21: PJa
B22: PRE | C22: =_xlfn.TEXTJOIN(",",TRUE,IF(LEFT(Regions!$C$3,1)<>"*",Regions!$C$3,""),IF(LEFT(Regions!$D$3,1)<>"*",Regions!$D$3,"")) -> IE,National | D22: =_xlfn.TEXTJOIN("-",TRUE,"FT",Commodities!D7) -> FT-INDOIL | E22: =_xlfn.TEXTJOIN(" - ",TRUE,"Fuel Tech",Commodities!E7) -> Fuel Tech - Oil products (IND) | F22: PJ | G22: PJa
B23: \I: | C23: =_xlfn.TEXTJOIN(",",TRUE,IF(LEFT(Regions!$C$3,1)<>"*",Regions!$C$3,""),IF(LEFT(Regions!$D$3,1)<>"*",Regions!$D$3,"")) -> IE,National | D23: =_xlfn.TEXTJOIN("-",TRUE,"FT",Commodities!D8) -> FT-INDBKE | E23: =_xlfn.TEXTJOIN(" - ",TRUE,"Fuel Tech",Commodities!E8) -> Fuel Tech - BioKerosene (IND) | F23: PJ | G23: PJa
B24: \I: | C24: =_xlfn.TEXTJOIN(",",TRUE,IF(LEFT(Regions!$C$3,1)<>"*",Regions!$C$3,""),IF(LEFT(Regions!$D$3,1)<>"*",Regions!$D$3,"")) -> IE,National | D24: =_xlfn.TEXTJOIN("-",TRUE,"FT",Commodities!D9) -> FT-INDHFO | E24: =_xlfn.TEXTJOIN(" - ",TRUE,"Fuel Tech",Commodities!E9) -> Fuel Tech - Heavy Fuel Oil (IND) | F24: PJ | G24: PJa
B25: \I: | C25: =_xlfn.TEXTJOIN(",",TRUE,IF(LEFT(Regions!$C$3,1)<>"*",Regions!$C$3,""),IF(LEFT(Regions!$D$3,1)<>"*",Regions!$D$3,"")) -> IE,National | D25: =_xlfn.TEXTJOIN("-",TRUE,"FT",Commodities!D10) -> FT-INDLPG | E25: =_xlfn.TEXTJOIN(" - ",TRUE,"Fuel Tech",Commodities!E10) -> Fuel Tech - Liquified Petroleum Gas (IND) | F25: PJ | G25: PJa
B26: \I: | C26: =_xlfn.TEXTJOIN(",",TRUE,IF(LEFT(Regions!$C$3,1)<>"*",Regions!$C$3,""),IF(LEFT(Regions!$D$3,1)<>"*",Regions!$D$3,"")) -> IE,National | D26: =_xlfn.TEXTJOIN("-",TRUE,"FT",Commodities!D11) -> FT-INDDST | E26: =_xlfn.TEXTJOIN(" - ",TRUE,"Fuel Tech",Commodities!E11) -> Fuel Tech - Diesel (IND) | F26: PJ | G26: PJa
B27: PRE | C27: =_xlfn.TEXTJOIN(",",TRUE,IF(LEFT(Regions!$C$3,1)<>"*",Regions!$C$3,""),IF(LEFT(Regions!$D$3,1)<>"*",Regions!$D$3,"")) -> IE,National | D27: =_xlfn.TEXTJOIN("-",TRUE,"FT",Commodities!D12) -> FT-INDWOO | E27: =_xlfn.TEXTJOIN(" - ",TRUE,"Fuel Tech",Commodities!E12) -> Fuel Tech - Solid biomass (IND) | F27: PJ | G27: PJa
B28: PRE | C28: =_xlfn.TEXTJOIN(",",TRUE,IF(LEFT(Regions!$C$3,1)<>"*",Regions!$C$3,""),IF(LEFT(Regions!$D$3,1)<>"*",Regions!$D$3,"")) -> IE,National | D28: =_xlfn.TEXTJOIN("-",TRUE,"FT",Commodities!D13) -> FT-INDCOK | E28: =_xlfn.TEXTJOIN(" - ",TRUE,"Fuel Tech",Commodities!E13) -> Fuel Tech - Petroleum Coke (IND) | F28: PJ | G28: PJa
B29: PRE | C29: =_xlfn.TEXTJOIN(",",TRUE,IF(LEFT(Regions!$C$3,1)<>"*",Regions!$C$3,""),IF(LEFT(Regions!$D$3,1)<>"*",Regions!$D$3,"")) -> IE,National | D29: =_xlfn.TEXTJOIN("-",TRUE,"FT",Commodities!D14) -> FT-INDGAS | E29: =_xlfn.TEXTJOIN(" - ",TRUE,"Fuel Tech",Commodities!E14) -> Fuel Tech - Natural Gas (IND) | F29: PJ | G29: PJa
B30: PRE | C30: =_xlfn.TEXTJOIN(",",TRUE,IF(LEFT(Regions!$C$3,1)<>"*",Regions!$C$3,""),IF(LEFT(Regions!$D$3,1)<>"*",Regions!$D$3,"")) -> IE,National | D30: =_xlfn.TEXTJOIN("-",TRUE,"FT",Commodities!D19) -> FT-INDELC | E30: =_xlfn.TEXTJOIN(" - ",TRUE,"Fuel Tech",Commodities!E19) -> Fuel Tech - Electricity (IND) | F30: PJ | G30: PJa | H30: DAYNITE
B31: PRE | C31: =_xlfn.TEXTJOIN(",",TRUE,IF(LEFT(Regions!$C$3,1)<>"*",Regions!$C$3,""),IF(LEFT(Regions!$D$3,1)<>"*",Regions!$D$3,"")) -> IE,National | D31: =_xlfn.TEXTJOIN("-",TRUE,"FT",Commodities!D20) -> FT-INDBGS | E31: =_xlfn.TEXTJOIN(" - ",TRUE,"Fuel Tech",Commodities!E20) -> Fuel Tech - Biogas (IND) | F31: PJ | G31: PJa
B32: PRE | C32: =_xlfn.TEXTJOIN(",",TRUE,IF(LEFT(Regions!$C$3,1)<>"*",Regions!$C$3,""),IF(LEFT(Regions!$D$3,1)<>"*",Regions!$D$3,"")) -> IE,National | D32: =_xlfn.TEXTJOIN("-",TRUE,"FT",Commodities!D21) -> FT-INDBIO | E32: =_xlfn.TEXTJOIN(" - ",TRUE,"Fuel Tech",Commodities!E21) -> Fuel Tech - Biomass (IND) | F32: PJ | G32: PJa
B33: PRE | C33: =_xlfn.TEXTJOIN(",",TRUE,IF(LEFT(Regions!$C$3,1)<>"*",Regions!$C$3,""),IF(LEFT(Regions!$D$3,1)<>"*",Regions!$D$3,"")) -> IE,National | D33: =_xlfn.TEXTJOIN("-",TRUE,"FT",Commodities!D22) -> FT-INDRWS | E33: =_xlfn.TEXTJOIN(" - ",TRUE,"Fuel Tech",Commodities!E22) -> Fuel Tech - Renewable waste (IND) | F33: PJ | G33: PJa
B34: PRE | C34: =_xlfn.TEXTJOIN(",",TRUE,IF(LEFT(Regions!$C$3,1)<>"*",Regions!$C$3,""),IF(LEFT(Regions!$D$3,1)<>"*",Regions!$D$3,"")) -> IE,National | D34: =_xlfn.TEXTJOIN("-",TRUE,"FT",Commodities!D23) -> FT-INDNWS | E34: =_xlfn.TEXTJOIN(" - ",TRUE,"Fuel Tech",Commodities!E23) -> Fuel Tech - Non-renewable waste (IND) | F34: PJ | G34: PJa
B35: PRE | C35: =_xlfn.TEXTJOIN(",",TRUE,IF(LEFT(Regions!$C$3,1)<>"*",Regions!$C$3,""),IF(LEFT(Regions!$D$3,1)<>"*",Regions!$D$3,"")) -> IE,National | D35: =_xlfn.TEXTJOIN("-",TRUE,"FT",Commodities!D24) -> FT-INDH2G | E35: =_xlfn.TEXTJOIN(" - ",TRUE,"Fuel Tech",Commodities!E24) -> Fuel Tech - Hydrogen gaseous (IND) | F35: PJ | G35: PJa
B36: PRE | C36: =_xlfn.TEXTJOIN(",",TRUE,IF(LEFT(Regions!$C$3,1)<>"*",Regions!$C$3,""),IF(LEFT(Regions!$D$3,1)<>"*",Regions!$D$3,"")) -> IE,National | D36: =_xlfn.TEXTJOIN("-",TRUE,"FT",Commodities!D25) -> FT-INDH2L | E36: =_xlfn.TEXTJOIN(" - ",TRUE,"Fuel Tech",Commodities!E25) -> Fuel Tech - Hydrogen liquid (IND) | F36: PJ | G36: PJa
B37: PRE | C37: =_xlfn.TEXTJOIN(",",TRUE,IF(LEFT(Regions!$C$3,1)<>"*",Regions!$C$3,""),IF(LEFT(Regions!$D$3,1)<>"*",Regions!$D$3,"")) -> IE,National | D37: =+Techs!B6 -> I-CEM-KLN-NWS-ETS_E0 | E37: =+Techs!C6 -> Industry - Cement - Cement/Lime Kiln - Non-bio waste - ETS | F37: MW | G37: PJa
B38: PRE | C38: =_xlfn.TEXTJOIN(",",TRUE,IF(LEFT(Regions!$C$3,1)<>"*",Regions!$C$3,""),IF(LEFT(Regions!$D$3,1)<>"*",Regions!$D$3,"")) -> IE,National | D38: =+Techs!B7 -> I-CEM-DRR-NWS-ETS_E0 | E38: =+Techs!C7 -> Industry - Cement - Dryer - Non-bio waste - ETS | F38: MW | G38: PJa
B39: PRE | C39: =_xlfn.TEXTJOIN(",",TRUE,IF(LEFT(Regions!$C$3,1)<>"*",Regions!$C$3,""),IF(LEFT(Regions!$D$3,1)<>"*",Regions!$D$3,"")) -> IE,National | D39: =+Techs!B8 -> I-CEM-KLN-RWS-ETS_E0 | E39: =+Techs!C8 -> Industry - Cement - Cement/Lime Kiln - Bio waste - ETS | F39: MW | G39: PJa
B40: PRE | C40: =_xlfn.TEXTJOIN(",",TRUE,IF(LEFT(Regions!$C$3,1)<>"*",Regions!$C$3,""),IF(LEFT(Regions!$D$3,1)<>"*",Regions!$D$3,"")) -> IE,National | D40: =+Techs!B9 -> I-CEM-DRR-RWS-ETS_E0 | E40: =+Techs!C9 -> Industry - Cement - Dryer - Bio waste - ETS | F40: MW | G40: PJa
B41: PRE | C41: =_xlfn.TEXTJOIN(",",TRUE,IF(LEFT(Regions!$C$3,1)<>"*",Regions!$C$3,""),IF(LEFT(Regions!$D$3,1)<>"*",Regions!$D$3,"")) -> IE,National | D41: =+Techs!B10 -> I-CEM-KLN-COA-ETS_E0 | E41: =+Techs!C10 -> Industry - Cement - Cement/Lime Kiln - Solid Fuels - ETS | F41: MW | G41: PJa
B42: PRE | C42: =_xlfn.TEXTJOIN(",",TRUE,IF(LEFT(Regions!$C$3,1)<>"*",Regions!$C$3,""),IF(LEFT(Regions!$D$3,1)<>"*",Regions!$D$3,"")) -> IE,National | D42: =+Techs!B11 -> I-CEM-DRR-COA-ETS_E0 | E42: =+Techs!C11 -> Industry - Cement - Dryer - Solid Fuels - ETS | F42: MW | G42: PJa
...

Sheet FT
F2: ~FI_T
B3: Region | C3: TechName | D3: *TechDesc | E3: Comm-IN | F3: Comm-OUT | G3: EFF | H3: NCAP_TLIFE | I3: Share-I | J3: Share-I~0 | K3: COST
B4: *Region Name | C4: Technology Name | D4: Technology Description | E4: Input Commodity | F4: Output Commodity | G4: Efficiency | H4: Lifetime | I4: Input share | J4: Input share interpolation
B5: *Units | H5: Years | I5: %
B6: =_xlfn.TEXTJOIN(",",TRUE,IF(LEFT(Regions!$C$3,1)<>"*",Regions!$C$3,""),IF(LEFT(Regions!$D$3,1)<>"*",Regions!$D$3,"")) -> IE,National | C6: =Processes!D20 -> FT-INDCOA | D6: =Processes!E20 -> Fuel Tech - Coal (IND) | E6: COABIT | F6: =Commodities!D5 -> INDCOA | G6: 1 | H6: 50
B7: =_xlfn.TEXTJOIN(",",TRUE,IF(LEFT(Regions!$C$3,1)<>"*",Regions!$C$3,""),IF(LEFT(Regions!$D$3,1)<>"*",Regions!$D$3,"")) -> IE,National | C7: =Processes!D21 -> FT-INDPEA | D7: =Processes!E21 -> Fuel Tech - Peat (IND) | E7: PEAT | F7: =Commodities!D6 -> INDPEA | G7: 1 | H7: 50
B8: =_xlfn.TEXTJOIN(",",TRUE,IF(LEFT(Regions!$C$3,1)<>"*",Regions!$C$3,""),IF(LEFT(Regions!$D$3,1)<>"*",Regions!$D$3,"")) -> IE,National | C8: =Processes!D22 -> FT-INDOIL | D8: =Processes!E22 -> Fuel Tech - Oil products (IND) | E8: OILKER | F8: =Commodities!D7 -> INDOIL | G8: 1 | H8: 50 | I8: 0.04 | J8: 5
E9: BIOJKR | I9: 0 | J9: 5
E10: OILHFO | I10: 0.18 | J10: 5
E11: OILLPG | I11: =1-SUM(I8:I10,I12:I13) -> 0.23 | J11: 5
E12: OILDST | I12: 0.55 | J12: 5
E13: BIODST1G,BIODST2G | I13: 0 | J13: 5
B14: =_xlfn.TEXTJOIN(",",TRUE,IF(LEFT(Regions!$C$3,1)<>"*",Regions!$C$3,""),IF(LEFT(Regions!$D$3,1)<>"*",Regions!$D$3,"")) -> IE,National | C14: =Processes!D28 -> FT-INDCOK | D14: =Processes!E28 -> Fuel Tech - Petroleum Coke (IND) | E14: OILCOK | F14: =Commodities!D13 -> INDCOK | G14: 1 | H14: 50
B15: =_xlfn.TEXTJOIN(",",TRUE,IF(LEFT(Regions!$C$3,1)<>"*",Regions!$C$3,""),IF(LEFT(Regions!$D$3,1)<>"*",Regions!$D$3,"")) -> IE,National | C15: =Processes!D29 -> FT-INDGAS | D15: =Processes!E29 -> Fuel Tech - Natural Gas (IND) | E15: GASNAT | F15: =Commodities!D14 -> INDGAS | G15: 1 | H15: 50
B16: =_xlfn.TEXTJOIN(",",TRUE,IF(LEFT(Regions!$C$3,1)<>"*",Regions!$C$3,""),IF(LEFT(Regions!$D$3,1)<>"*",Regions!$D$3,"")) -> IE,National | C16: =Processes!D30 -> FT-INDELC | D16: =Processes!E30 -> Fuel Tech - Electricity (IND) | E16: ELCD | F16: =Commodities!D19 -> INDELC | G16: 1 | H16: 50
B17: =_xlfn.TEXTJOIN(",",TRUE,IF(LEFT(Regions!$C$3,1)<>"*",Regions!$C$3,""),IF(LEFT(Regions!$D$3,1)<>"*",Regions!$D$3,"")) -> IE,National | C17: =Processes!D31 -> FT-INDBGS | D17: =Processes!E31 -> Fuel Tech - Biogas (IND) | E17: BIOGAS1G,BIOGAS2G | F17: =Commodities!D20 -> INDBGS | G17: 1 | H17: 50
B18: =_xlfn.TEXTJOIN(",",TRUE,IF(LEFT(Regions!$C$3,1)<>"*",Regions!$C$3,""),IF(LEFT(Regions!$D$3,1)<>"*",Regions!$D$3,"")) -> IE,National | C18: =Processes!D32 -> FT-INDBIO | D18: =Processes!E32 -> Fuel Tech - Biomass (IND) | E18: BIOWPE,BIOWCH,BIOWOO,BIOWOO1,BIOINDF | F18: =Commodities!D21 -> INDBIO | G18: 1 | H18: 50
B19: =_xlfn.TEXTJOIN(",",TRUE,IF(LEFT(Regions!$C$3,1)<>"*",Regions!$C$3,""),IF(LEFT(Regions!$D$3,1)<>"*",Regions!$D$3,"")) -> IE,National | C19: =Processes!D33 -> FT-INDRWS | D19: =Processes!E33 -> Fuel Tech - Renewable waste (IND) | E19: BIOWOO2,BIOMSW1,BIOMUN | F19: =Commodities!D22 -> INDRWS | G19: 1 | H19: 50
B20: =_xlfn.TEXTJOIN(",",TRUE,IF(LEFT(Regions!$C$3,1)<>"*",Regions!$C$3,""),IF(LEFT(Regions!$D$3,1)<>"*",Regions!$D$3,"")) -> IE,National | C20: =Processes!D34 -> FT-INDNWS | D20: =Processes!E34 -> Fuel Tech - Non-renewable waste (IND) | E20: WASTE | F20: =Commodities!D23 -> INDNWS | G20: 1 | H20: 50
B21: =_xlfn.TEXTJOIN(",",TRUE,IF(LEFT(Regions!$C$3,1)<>"*",Regions!$C$3,""),IF(LEFT(Regions!$D$3,1)<>"*",Regions!$D$3,"")) -> IE,National | C21: =Processes!D35 -> FT-INDH2G | D21: =Processes!E35 -> Fuel Tech - Hydrogen gaseous (IND) | E21: SUPH2GC, SUPH2GD | F21: =Commodities!D24 -> INDH2G | G21: 1 | H21: 50
B22: =_xlfn.TEXTJOIN(",",TRUE,IF(LEFT(Regions!$C$3,1)<>"*",Regions!$C$3,""),IF(LEFT(Regions!$D$3,1)<>"*",Regions!$D$3,"")) -> IE,National | C22: =Processes!D36 -> FT-INDH2L | D22: =Processes!E36 -> Fuel Tech - Hydrogen liquid (IND) | E22: SUPH2LC, SUPH2LD | F22: =Commodities!D25 -> INDH2L | G22: 1 | H22: 50
B23: =_xlfn.TEXTJOIN(",",TRUE,IF(LEFT(Regions!$C$3,1)<>"*",Regions!$C$3,""),IF(LEFT(Regions!$D$3,1)<>"*",Regions!$D$3,"")) -> IE,National | C23: =+Processes!D27 -> FT-INDWOO | D23: =+Processes!E27 -> Fuel Tech - Solid biomass (IND) | E23: BIOWPE,BIOWCH,BIOWOO,BIOWOO1 | F23: =+Commodities!D12 -> INDWOO | G23: 1 | H23: 50
B24: =_xlfn.TEXTJOIN(",",TRUE,IF(LEFT(Regions!$C$3,1)<>"*",Regions!$C$3,""),IF(LEFT(Regions!$D$3,1)<>"*",Regions!$D$3,"")) -> IE,National | C24: =Processes!D141 -> MIN-WASTE | F24: =+E20 -> WASTE | G24: 1 | K24: 10

Sheet DMD
F2: ~FI_T
B3: Region | C3: TechName | D3: *TechDesc | E3: Comm-IN | F3: Comm-OUT | G3: EFF | H3: NCAP_TLIFE | I3: SHARE-I~UP~2018 | J3: *SHARE-I~UP~2019 | K3: *SHARE-I~UP~2020 | L3: ENV_ACT~INDCO2P | M3: SHARE-I~UP~0
B4: *Region Name | C4: Technology Name | D4: Technology Description | E4: Input Commodity | F4: Output Commodity | G4: Efficiency | H4: Lifetime | I4: Input Share | M4: Input Share
B5: *Units | H5: Years | M5: I/E rule
B6: =_xlfn.TEXTJOIN(",",TRUE,IF(LEFT(Regions!$C$3,1)<>"*",Regions!$C$3,""),IF(LEFT(Regions!$D$3,1)<>"*",Regions!$D$3,"")) -> IE,National | C6: ="I-DMD-"&R6&"-E0" -> I-DMD-CEM-E0 | D6: =Processes!E5 -> Cement industry demand process | F6: =Commodities!D27 -> ICEM | G6: 1 | H6: 50 | L6: =+EMI!K28 -> 197.87212 | Q6: Cement | R6: CEM
E7: =RIGHT(F6,3)&"HTH" -> CEMHTH | I7: =VLOOKUP(O7,NRG_shares!$R$196:$W$204,DMD!P7,FALSE) -> 0.96935376 | M7: 5 | O7: Cement | P7: 3 | Q7: Chemicals | R7: CAF
E8: =RIGHT(F6,3)&"MTH" -> CEMMTH | I8: =VLOOKUP(O8,NRG_shares!$R$196:$W$204,DMD!P8,FALSE) -> 0.030646236 | M8: 5 | O8: Cement | P8: 4 | Q8: Food and Drink | R8: FAP
B9: \I: | E9: =RIGHT(F6,3)&"LTH" -> CEMLTH | I9: =VLOOKUP(O9,NRG_shares!$R$196:$W$204,DMD!P9,FALSE) -> 0 | M9: 5 | O9: Cement | P9: 5 | Q9: Lime | R9: LIM
B10: \I: | E10: =RIGHT(F6,3)&"HET" -> CEMHET | I10: =VLOOKUP(O10,NRG_shares!$R$196:$W$204,DMD!P10,FALSE) -> 0 | M10: 5 | O10: Cement | P10: 6 | Q10: Metals | R10: MAP
B11: =_xlfn.TEXTJOIN(",",TRUE,IF(LEFT(Regions!$C$3,1)<>"*",Regions!$C$3,""),IF(LEFT(Regions!$D$3,1)<>"*",Regions!$D$3,"")) -> IE,National | C11: ="I-DMD-"&R7&"-E0" -> I-DMD-CAF-E0 | D11: =Processes!E6 -> Chemicals industry demand process | F11: =Commodities!D28 -> ICAF | G11: 1 | H11: 50 | Q11: Other Industry | R11: OMA
B12: \I: | E12: =RIGHT(F11,3)&"HTH" -> CAFHTH | I12: =VLOOKUP(O12,NRG_shares!$R$196:$W$204,DMD!P12,FALSE) -> 0 | M12: 5 | O12: Chemicals | P12: 3 | Q12: Other Minerals | R12: ONM
E13: =RIGHT(F11,3)&"MTH" -> CAFMTH | I13: =VLOOKUP(O13,NRG_shares!$R$196:$W$204,DMD!P13,FALSE) -> 0.29754119 | M13: 5 | O13: Chemicals | P13: 4 | Q13: Refining | R13: REF
E14: =RIGHT(F11,3)&"LTH" -> CAFLTH | I14: =VLOOKUP(O14,NRG_shares!$R$196:$W$204,DMD!P14,FALSE) -> 0.56606521 | M14: 5 | O14: Chemicals | P14: 5 | Q14: Wood Products | R14: WAP
E15: =RIGHT(F11,3)&"HET" -> CAFHET | I15: =VLOOKUP(O15,NRG_shares!$R$196:$W$204,DMD!P15,FALSE) -> 0.1363936 | M15: 5 | O15: Chemicals | P15: 6
B16: =_xlfn.TEXTJOIN(",",TRUE,IF(LEFT(Regions!$C$3,1)<>"*",Regions!$C$3,""),IF(LEFT(Regions!$D$3,1)<>"*",Regions!$D$3,"")) -> IE,National | C16: ="I-DMD-"&R8&"-E0" -> I-DMD-FAP-E0 | D16: =Processes!E7 -> Food and Drink demand process | F16: =Commodities!D29 -> IFAP | G16: 1 | H16: 50
B17: \I: | E17: =RIGHT(F16,3)&"HTH" -> FAPHTH | I17: =VLOOKUP(O17,NRG_shares!$R$196:$W$204,DMD!P17,FALSE) -> 0 | M17: 5 | O17: Food and Drink | P17: 3
E18: =RIGHT(F16,3)&"MTH" -> FAPMTH | I18: =VLOOKUP(O18,NRG_shares!$R$196:$W$204,DMD!P18,FALSE) -> 0.17739819 | M18: 5 | O18: Food and Drink | P18: 4
E19: =RIGHT(F16,3)&"LTH" -> FAPLTH | I19: =VLOOKUP(O19,NRG_shares!$R$196:$W$204,DMD!P19,FALSE) -> 0.59622478 | M19: 5 | O19: Food and Drink | P19: 5
E20: =RIGHT(F16,3)&"HET" -> FAPHET | I20: =VLOOKUP(O20,NRG_shares!$R$196:$W$204,DMD!P20,FALSE) -> 0.22637704 | M20: 5 | O20: Food and Drink | P20: 6
B21: =_xlfn.TEXTJOIN(",",TRUE,IF(LEFT(Regions!$C$3,1)<>"*",Regions!$C$3,""),IF(LEFT(Regions!$D$3,1)<>"*",Regions!$D$3,"")) -> IE,National | C21: ="I-DMD-"&R9&"-E0" -> I-DMD-LIM-E0 | D21: =Processes!E8 -> Lime demand process | F21: =Commodities!D30 -> ILIM | G21: 1 | H21: 50
E22: =RIGHT(F21,3)&"HTH" -> LIMHTH | I22: =VLOOKUP(O22,NRG_shares!$R$196:$W$204,DMD!P22,FALSE) -> 1 | M22: 5 | O22: Lime | P22: 3
B23: \I: | E23: =RIGHT(F21,3)&"MTH" -> LIMMTH | I23: =VLOOKUP(O23,NRG_shares!$R$196:$W$204,DMD!P23,FALSE) -> 0 | M23: 5 | O23: Lime | P23: 4
B24: \I: | E24: =RIGHT(F21,3)&"LTH" -> LIMLTH | I24: =VLOOKUP(O24,NRG_shares!$R$196:$W$204,DMD!P24,FALSE) -> 0 | M24: 5 | O24: Lime | P24: 5
B25: \I: | E25: =RIGHT(F21,3)&"HET" -> LIMHET | I25: =VLOOKUP(O25,NRG_shares!$R$196:$W$204,DMD!P25,FALSE) -> 0 | M25: 5 | O25: Lime | P25: 6
B26: =_xlfn.TEXTJOIN(",",TRUE,IF(LEFT(Regions!$C$3,1)<>"*",Regions!$C$3,""),IF(LEFT(Regions!$D$3,1)<>"*",Regions!$D$3,"")) -> IE,National | C26: ="I-DMD-"&R10&"-E0" -> I-DMD-MAP-E0 | D26: =Processes!E9 -> Metals demand process | F26: =Commodities!D31 -> IMAP | G26: 1 | H26: 50
E27: =RIGHT(F26,3)&"HTH" -> MAPHTH | I27: =VLOOKUP(O27,NRG_shares!$R$196:$W$204,DMD!P27,FALSE) -> 0.25515793 | M27: 5 | O27: Metals | P27: 3
E28: =RIGHT(F26,3)&"MTH" -> MAPMTH | I28: =VLOOKUP(O28,NRG_shares!$R$196:$W$204,DMD!P28,FALSE) -> 0.74484207 | M28: 5 | O28: Metals | P28: 4
B29: \I: | E29: =RIGHT(F26,3)&"LTH" -> MAPLTH | I29: =VLOOKUP(O29,NRG_shares!$R$196:$W$204,DMD!P29,FALSE) -> 0 | M29: 5 | O29: Metals | P29: 5
B30: \I: | E30: =RIGHT(F26,3)&"HET" -> MAPHET | I30: =VLOOKUP(O30,NRG_shares!$R$196:$W$204,DMD!P30,FALSE) -> 0 | M30: 5 | O30: Metals | P30: 6
B31: =_xlfn.TEXTJOIN(",",TRUE,IF(LEFT(Regions!$C$3,1)<>"*",Regions!$C$3,""),IF(LEFT(Regions!$D$3,1)<>"*",Regions!$D$3,"")) -> IE,National | C31: ="I-DMD-"&R11&"-E0" -> I-DMD-OMA-E0 | D31: =Processes!E10 -> Other Industry demand process | F31: =Commodities!D32 -> IOMA | G31: 1 | H31: 50
E32: =RIGHT(F31,3)&"HTH" -> OMAHTH | I32: =VLOOKUP(O32,NRG_shares!$R$196:$W$204,DMD!P32,FALSE) -> 0.034765579 | M32: 5 | O32: Other Industry | P32: 3
B33: \I: | E33: =RIGHT(F31,3)&"MTH" -> OMAMTH | I33: =VLOOKUP(O33,NRG_shares!$R$196:$W$204,DMD!P33,FALSE) -> 0 | M33: 5 | O33: Other Industry | P33: 4
E34: =RIGHT(F31,3)&"LTH" -> OMALTH | I34: =VLOOKUP(O34,NRG_shares!$R$196:$W$204,DMD!P34,FALSE) -> 0.70864455 | M34: 5 | O34: Other Industry | P34: 5
E35: =RIGHT(F31,3)&"HET" -> OMAHET | I35: =VLOOKUP(O35,NRG_shares!$R$196:$W$204,DMD!P35,FALSE) -> 0.25658987 | M35: 5 | O35: Other Industry | P35: 6
B36: =_xlfn.TEXTJOIN(",",TRUE,IF(LEFT(Regions!$C$3,1)<>"*",Regions!$C$3,""),IF(LEFT(Regions!$D$3,1)<>"*",Regions!$D$3,"")) -> IE,National | C36: ="I-DMD-"&R12&"-E0" -> I-DMD-ONM-E0 | D36: =Processes!E11 -> Other non-metallic minerals process | F36: =Commodities!D33 -> IONM | G36: 1 | H36: 50
E37: =RIGHT(F36,3)&"HTH" -> ONMHTH | I37: =VLOOKUP(O37,NRG_shares!$R$196:$W$204,DMD!P37,FALSE) -> 0.16901133 | M37: 5 | O37: Other Minerals | P37: 3
E38: =RIGHT(F36,3)&"MTH" -> ONMMTH | I38: =VLOOKUP(O38,NRG_shares!$R$196:$W$204,DMD!P38,FALSE) -> 0.4294553 | M38: 5 | O38: Other Minerals | P38: 4
E39: =RIGHT(F36,3)&"LTH" -> ONMLTH | I39: =VLOOKUP(O39,NRG_shares!$R$196:$W$204,DMD!P39,FALSE) -> 0.40153337 | M39: 5 | O39: Other Minerals | P39: 5
B40: \I: | E40: =RIGHT(F36,3)&"HET" -> ONMHET | I40: =VLOOKUP(O40,NRG_shares!$R$196:$W$204,DMD!P40,FALSE) -> 0 | M40: 5 | O40: Other Minerals | P40: 6
B41: =_xlfn.TEXTJOIN(",",TRUE,IF(LEFT(Regions!$C$3,1)<>"*",Regions!$C$3,""),IF(LEFT(Regions!$D$3,1)<>"*",Regions!$D$3,"")) -> IE,National | C41: ="I-DMD-"&R14&"-E0" -> I-DMD-WAP-E0 | D41: =Processes!E13 -> Wood Products demand process | F41: =Commodities!D35 -> IWAP | G41: 1 | H41: 50
...

Sheet Techs
Q1: Empty column
X2: For definition of processes and commoditites
E3: ~FI_T | T3: ~FI_T
B4: TechName | C4: *TechDesc | D4: Comm-IN | E4: Comm-OUT | F4: EFF | G4: LIFE | H4: Stock | I4: CAP2ACT | J4: CF | K4: *SHARE-O~UP~INDHTH | L4: *SHARE-O~UP~INDMTH | M4: *SHARE-O~UP~INDLTH | N4: *SHARE-O~UP~INDHET | O4: *SHARE-O~UP~0 | P4: *Output | R4: TechName | S4: Attribute | T4: Commodity | U4: 2018 | V4: 0
B5: *Technology Name | C5: Technology Description | D5: Input Commodity | E5: Output Commodity | F5: Efficiency | G5: Lifetime | H5: Input Share | I5: Capacity unit | J5: Availability | K5: Output share of heat temperature | L5: Output share of heat temperature | M5: Output share of heat temperature | N5: Output share of heat temperature | O5: Output share of heat temperature | P5: *Calibration | R5: *Technology Name | S5: Attribute | T5: Commodity name | U5: 2018 | AE5: Sector | AF5: Code
B6: ="I-"&VLOOKUP(Y6,$AE$6:$AF$71,2,FALSE)&"-"&VLOOKUP(AA6,$AE$6:$AF$71,2,FALSE)&"-"&VLOOKUP(AB6,$AE$6:$AF$71,2,FALSE)&"-"&VLOOKUP(Z6,$AE$6:$AF$71,2,FALSE)&"_E0" -> I-CEM-KLN-NWS-ETS_E0 | C6: =_xlfn.TEXTJOIN(" - ",TRUE,X6,Y6,AA6,AB6,Z6) -> Industry - Cement - Cement/Lime Kiln - Non-bio waste - ETS | D6: =VLOOKUP(AB6,$AE$64:$AG$69,3,FALSE) -> INDNWS | E6: =VLOOKUP(Y6,$AE$6:$AF$71,2,FALSE)&"HTH,"&VLOOKUP(Y6,$AE$6:$AF$71,2,FALSE)&"MTH,"&VLOOKUP(Y6,$AE$6:$AF$71,2,FALSE)&"LTH,"&VLOOKUP(Y6,$AE$6:$AF$71,2,FALSE)&"HET" -> CEMHTH,CEMMTH,CEMLTH,CEMHET | F6: =+NRG_shares!V4 -> 0.9 | G6: 25 | H6: =IF(P6/I6/J6*1.075<0.001,0,P6/I6/J6*1.075) -> 0.078039571 | I6: 31.536 | J6: 0.9 | K6: =+SUMIFS(NRG_shares!W$113:W$141,NRG_shares!$T$113:$T$141,Techs!$Y6,NRG_shares!$U$113:$U$141,Techs!$AA6) -> 1 | L6: =+SUMIFS(NRG_shares!X$113:X$141,NRG_shares!$T$113:$T$141,Techs!$Y6,NRG_shares!$U$113:$U$141,Techs!$AA6) -> 0 | M6: =+SUMIFS(NRG_shares!Y$113:Y$141,NRG_shares!$T$113:$T$141,Techs!$Y6,NRG_shares!$U$113:$U$141,Techs!$AA6) -> 0 | N6: =+SUMIFS(NRG_shares!Z$113:Z$141,NRG_shares!$T$113:$T$141,Techs!$Y6,NRG_shares!$U$113:$U$141,Techs!$AA6) -> 0 | O6: 3 | P6: =NRG_shares!J4*NRG_shares!O4*Conversions!$B$3 -> 2.0604189 | R6: {=_xlfn.TOCOL(AM6:AP109,0,FALSE)} -> I-CEM-KLN-NWS-ETS_E0 | S6: Share-O | T6: {=_xlfn.TOCOL(AH6:AK109,0,FALSE)} -> CEMHTH | U6: {=_xlfn.TOCOL(K6:N109,0,FALSE)} -> 1 | V6: 3 | X6: Industry | Y6: Cement | Z6: ETS | AA6: Cement/Lime Kiln | AB6: Non-bio waste | AE6: Cement | AF6: CEM | AH6: CEMHTH | AI6: CEMMTH | AJ6: CEMLTH | AK6: CEMHET | AM6: =+B6 -> I-CEM-KLN-NWS-ETS_E0 | AN6: =+AM6 -> I-CEM-KLN-NWS-ETS_E0 | AO6: =+AN6 -> I-CEM-KLN-NWS-ETS_E0 | AP6: =+AO6 -> I-CEM-KLN-NWS-ETS_E0
B7: ="I-"&VLOOKUP(Y7,$AE$6:$AF$71,2,FALSE)&"-"&VLOOKUP(AA7,$AE$6:$AF$71,2,FALSE)&"-"&VLOOKUP(AB7,$AE$6:$AF$71,2,FALSE)&"-"&VLOOKUP(Z7,$AE$6:$AF$71,2,FALSE)&"_E0" -> I-CEM-DRR-NWS-ETS_E0 | C7: =_xlfn.TEXTJOIN(" - ",TRUE,X7,Y7,AA7,AB7,Z7) -> Industry - Cement - Dryer - Non-bio waste - ETS | D7: =VLOOKUP(AB7,$AE$64:$AG$69,3,FALSE) -> INDNWS | E7: =VLOOKUP(Y7,$AE$6:$AF$71,2,FALSE)&"HTH,"&VLOOKUP(Y7,$AE$6:$AF$71,2,FALSE)&"MTH,"&VLOOKUP(Y7,$AE$6:$AF$71,2,FALSE)&"LTH,"&VLOOKUP(Y7,$AE$6:$AF$71,2,FALSE)&"HET" -> CEMHTH,CEMMTH,CEMLTH,CEMHET | F7: =+NRG_shares!V5 -> 0.92 | G7: 25 | H7: =IF(P7/I7/J7*1.075<0.001,0,P7/I7/J7*1.075) -> 0.0024672304 | I7: 31.536 | J7: 0.9 | K7: =+SUMIFS(NRG_shares!W$113:W$141,NRG_shares!$T$113:$T$141,Techs!$Y7,NRG_shares!$U$113:$U$141,Techs!$AA7) -> 0 | L7: =+SUMIFS(NRG_shares!X$113:X$141,NRG_shares!$T$113:$T$141,Techs!$Y7,NRG_shares!$U$113:$U$141,Techs!$AA7) -> 1 | M7: =+SUMIFS(NRG_shares!Y$113:Y$141,NRG_shares!$T$113:$T$141,Techs!$Y7,NRG_shares!$U$113:$U$141,Techs!$AA7) -> 0 | N7: =+SUMIFS(NRG_shares!Z$113:Z$141,NRG_shares!$T$113:$T$141,Techs!$Y7,NRG_shares!$U$113:$U$141,Techs!$AA7) -> 0 | O7: 3 | P7: =NRG_shares!J5*NRG_shares!O5*Conversions!$B$3 -> 0.065140391 | R7: I-CEM-KLN-NWS-ETS_E0 | S7: Share-O | T7: CEMMTH | U7: 0 | V7: 3 | X7: Industry | Y7: Cement | Z7: ETS | AA7: Dryer | AB7: Non-bio waste | AE7: Cement | AF7: CEM | AH7: CEMHTH | AI7: CEMMTH | AJ7: CEMLTH | AK7: CEMHET | AM7: =+B7 -> I-CEM-DRR-NWS-ETS_E0 | AN7: =+AM7 -> I-CEM-DRR-NWS-ETS_E0 | AO7: =+AN7 -> I-CEM-DRR-NWS-ETS_E0 | AP7: =+AO7 -> I-CEM-DRR-NWS-ETS_E0
B8: ="I-"&VLOOKUP(Y8,$AE$6:$AF$71,2,FALSE)&"-"&VLOOKUP(AA8,$AE$6:$AF$71,2,FALSE)&"-"&VLOOKUP(AB8,$AE$6:$AF$71,2,FALSE)&"-"&VLOOKUP(Z8,$AE$6:$AF$71,2,FALSE)&"_E0" -> I-CEM-KLN-RWS-ETS_E0 | C8: =_xlfn.TEXTJOIN(" - ",TRUE,X8,Y8,AA8,AB8,Z8) -> Industry - Cement - Cement/Lime Kiln - Bio waste - ETS | D8: =VLOOKUP(AB8,$AE$64:$AG$69,3,FALSE) -> INDRWS | E8: =VLOOKUP(Y8,$AE$6:$AF$71,2,FALSE)&"HTH,"&VLOOKUP(Y8,$AE$6:$AF$71,2,FALSE)&"MTH,"&VLOOKUP(Y8,$AE$6:$AF$71,2,FALSE)&"LTH,"&VLOOKUP(Y8,$AE$6:$AF$71,2,FALSE)&"HET" -> CEMHTH,CEMMTH,CEMLTH,CEMHET | F8: =+NRG_shares!V6 -> 0.9 | G8: 25 | H8: =IF(P8/I8/J8*1.075<0.001,0,P8/I8/J8*1.075) -> 0.055920673 | I8: 31.536 | J8: 0.9 | K8: =+SUMIFS(NRG_shares!W$113:W$141,NRG_shares!$T$113:$T$141,Techs!$Y8,NRG_shares!$U$113:$U$141,Techs!$AA8) -> 1 | L8: =+SUMIFS(NRG_shares!X$113:X$141,NRG_shares!$T$113:$T$141,Techs!$Y8,NRG_shares!$U$113:$U$141,Techs!$AA8) -> 0 | M8: =+SUMIFS(NRG_shares!Y$113:Y$141,NRG_shares!$T$113:$T$141,Techs!$Y8,NRG_shares!$U$113:$U$141,Techs!$AA8) -> 0 | N8: =+SUMIFS(NRG_shares!Z$113:Z$141,NRG_shares!$T$113:$T$141,Techs!$Y8,NRG_shares!$U$113:$U$141,Techs!$AA8) -> 0 | O8: 3 | P8: =NRG_shares!J6*NRG_shares!O6*Conversions!$B$3 -> 1.4764306 | R8: I-CEM-KLN-NWS-ETS_E0 | S8: Share-O | T8: CEMLTH | U8: 0 | V8: 3 | X8: Industry | Y8: Cement | Z8: ETS | AA8: Cement/Lime Kiln | AB8: Bio waste | AE8: Chemicals | AF8: CAF | AH8: CEMHTH | AI8: CEMMTH | AJ8: CEMLTH | AK8: CEMHET | AM8: =+B8 -> I-CEM-KLN-RWS-ETS_E0 | AN8: =+AM8 -> I-CEM-KLN-RWS-ETS_E0 | AO8: =+AN8 -> I-CEM-KLN-RWS-ETS_E0 | AP8: =+AO8 -> I-CEM-KLN-RWS-ETS_E0
B9: ="I-"&VLOOKUP(Y9,$AE$6:$AF$71,2,FALSE)&"-"&VLOOKUP(AA9,$AE$6:$AF$71,2,FALSE)&"-"&VLOOKUP(AB9,$AE$6:$AF$71,2,FALSE)&"-"&VLOOKUP(Z9,$AE$6:$AF$71,2,FALSE)&"_E0" -> I-CEM-DRR-RWS-ETS_E0 | C9: =_xlfn.TEXTJOIN(" - ",TRUE,X9,Y9,AA9,AB9,Z9) -> Industry - Cement - Dryer - Bio waste - ETS | D9: =VLOOKUP(AB9,$AE$64:$AG$69,3,FALSE) -> INDRWS | E9: =VLOOKUP(Y9,$AE$6:$AF$71,2,FALSE)&"HTH,"&VLOOKUP(Y9,$AE$6:$AF$71,2,FALSE)&"MTH,"&VLOOKUP(Y9,$AE$6:$AF$71,2,FALSE)&"LTH,"&VLOOKUP(Y9,$AE$6:$AF$71,2,FALSE)&"HET" -> CEMHTH,CEMMTH,CEMLTH,CEMHET | F9: =+NRG_shares!V7 -> 0.92 | G9: 25 | H9: =IF(P9/I9/J9*1.075<0.001,0,P9/I9/J9*1.075) -> 0.0017679388 | I9: 31.536 | J9: 0.9 | K9: =+SUMIFS(NRG_shares!W$113:W$141,NRG_shares!$T$113:$T$141,Techs!$Y9,NRG_shares!$U$113:$U$141,Techs!$AA9) -> 0 | L9: =+SUMIFS(NRG_shares!X$113:X$141,NRG_shares!$T$113:$T$141,Techs!$Y9,NRG_shares!$U$113:$U$141,Techs!$AA9) -> 1 | M9: =+SUMIFS(NRG_shares!Y$113:Y$141,NRG_shares!$T$113:$T$141,Techs!$Y9,NRG_shares!$U$113:$U$141,Techs!$AA9) -> 0 | N9: =+SUMIFS(NRG_shares!Z$113:Z$141,NRG_shares!$T$113:$T$141,Techs!$Y9,NRG_shares!$U$113:$U$141,Techs!$AA9) -> 0 | O9: 3 | P9: =NRG_shares!J7*NRG_shares!O7*Conversions!$B$3 -> 0.046677531 | R9: I-CEM-KLN-NWS-ETS_E0 | S9: Share-O | T9: CEMHET | U9: 0 | V9: 3 | X9: Industry | Y9: Cement | Z9: ETS | AA9: Dryer | AB9: Bio waste | AE9: Chemicals | AF9: CAF | AH9: CEMHTH | AI9: CEMMTH | AJ9: CEMLTH | AK9: CEMHET | AM9: =+B9 -> I-CEM-DRR-RWS-ETS_E0 | AN9: =+AM9 -> I-CEM-DRR-RWS-ETS_E0 | AO9: =+AN9 -> I-CEM-DRR-RWS-ETS_E0 | AP9: =+AO9 -> I-CEM-DRR-RWS-ETS_E0
B10: ="I-"&VLOOKUP(Y10,$AE$6:$AF$71,2,FALSE)&"-"&VLOOKUP(AA10,$AE$6:$AF$71,2,FALSE)&"-"&VLOOKUP(AB10,$AE$6:$AF$71,2,FALSE)&"-"&VLOOKUP(Z10,$AE$6:$AF$71,2,FALSE)&"_E0" -> I-CEM-KLN-COA-ETS_E0 | C10: =_xlfn.TEXTJOIN(" - ",TRUE,X10,Y10,AA10,AB10,Z10) -> Industry - Cement - Cement/Lime Kiln - Solid Fuels - ETS | D10: =VLOOKUP(AB10,$AE$64:$AG$69,3,FALSE) -> INDCOA,INDCOK | E10: =VLOOKUP(Y10,$AE$6:$AF$71,2,FALSE)&"HTH,"&VLOOKUP(Y10,$AE$6:$AF$71,2,FALSE)&"MTH,"&VLOOKUP(Y10,$AE$6:$AF$71,2,FALSE)&"LTH,"&VLOOKUP(Y10,$AE$6:$AF$71,2,FALSE)&"HET" -> CEMHTH,CEMMTH,CEMLTH,CEMHET | F10: =+NRG_shares!V8 -> 0.9 | G10: 25 | H10: =IF(P10/I10/J10*1.075<0.001,0,P10/I10/J10*1.075) -> 0.24523579 | I10: 31.536 | J10: 0.9 | K10: =+SUMIFS(NRG_shares!W$113:W$141,NRG_shares!$T$113:$T$141,Techs!$Y10,NRG_shares!$U$113:$U$141,Techs!$AA10) -> 1 | L10: =+SUMIFS(NRG_shares!X$113:X$141,NRG_shares!$T$113:$T$141,Techs!$Y10,NRG_shares!$U$113:$U$141,Techs!$AA10) -> 0 | M10: =+SUMIFS(NRG_shares!Y$113:Y$141,NRG_shares!$T$113:$T$141,Techs!$Y10,NRG_shares!$U$113:$U$141,Techs!$AA10) -> 0 | N10: =+SUMIFS(NRG_shares!Z$113:Z$141,NRG_shares!$T$113:$T$141,Techs!$Y10,NRG_shares!$U$113:$U$141,Techs!$AA10) -> 0 | O10: 3 | P10: =NRG_shares!J8*NRG_shares!O8*Conversions!$B$3 -> 6.4747724 | R10: I-CEM-DRR-NWS-ETS_E0 | S10: Share-O | T10: CEMHTH | U10: 0 | V10: 3 | X10: Industry | Y10: Cement | Z10: ETS | AA10: Cement/Lime Kiln | AB10: Solid Fuels | AE10: Chemicals | AF10: CAF | AH10: CEMHTH | AI10: CEMMTH | AJ10: CEMLTH | AK10: CEMHET | AM10: =+B10 -> I-CEM-KLN-COA-ETS_E0 | AN10: =+AM10 -> I-CEM-KLN-COA-ETS_E0 | AO10: =+AN10 -> I-CEM-KLN-COA-ETS_E0 | AP10: =+AO10 -> I-CEM-KLN-COA-ETS_E0
B11: ="I-"&VLOOKUP(Y11,$AE$6:$AF$71,2,FALSE)&"-"&VLOOKUP(AA11,$AE$6:$AF$71,2,FALSE)&"-"&VLOOKUP(AB11,$AE$6:$AF$71,2,FALSE)&"-"&VLOOKUP(Z11,$AE$6:$AF$71,2,FALSE)&"_E0" -> I-CEM-DRR-COA-ETS_E0 | C11: =_xlfn.TEXTJOIN(" - ",TRUE,X11,Y11,AA11,AB11,Z11) -> Industry - Cement - Dryer - Solid Fuels - ETS | D11: =VLOOKUP(AB11,$AE$64:$AG$69,3,FALSE) -> INDCOA,INDCOK | E11: =VLOOKUP(Y11,$AE$6:$AF$71,2,FALSE)&"HTH,"&VLOOKUP(Y11,$AE$6:$AF$71,2,FALSE)&"MTH,"&VLOOKUP(Y11,$AE$6:$AF$71,2,FALSE)&"LTH,"&VLOOKUP(Y11,$AE$6:$AF$71,2,FALSE)&"HET" -> CEMHTH,CEMMTH,CEMLTH,CEMHET | F11: =+NRG_shares!V9 -> 0.92 | G11: 25 | H11: =IF(P11/I11/J11*1.075<0.001,0,P11/I11/J11*1.075) -> 0.0077531591 | I11: 31.536 | J11: 0.9 | K11: =+SUMIFS(NRG_shares!W$113:W$141,NRG_shares!$T$113:$T$141,Techs!$Y11,NRG_shares!$U$113:$U$141,Techs!$AA11) -> 0 | L11: =+SUMIFS(NRG_shares!X$113:X$141,NRG_shares!$T$113:$T$141,Techs!$Y11,NRG_shares!$U$113:$U$141,Techs!$AA11) -> 1 | M11: =+SUMIFS(NRG_shares!Y$113:Y$141,NRG_shares!$T$113:$T$141,Techs!$Y11,NRG_shares!$U$113:$U$141,Techs!$AA11) -> 0 | N11: =+SUMIFS(NRG_shares!Z$113:Z$141,NRG_shares!$T$113:$T$141,Techs!$Y11,NRG_shares!$U$113:$U$141,Techs!$AA11) -> 0 | O11: 3 | P11: =NRG_shares!J9*NRG_shares!O9*Conversions!$B$3 -> 0.20470071 | R11: I-CEM-DRR-NWS-ETS_E0 | S11: Share-O | T11: CEMMTH | U11: 1 | V11: 3 | X11: Industry | Y11: Cement | Z11: ETS | AA11: Dryer | AB11: Solid Fuels | AE11: Chemicals | AF11: CAF | AH11: CEMHTH | AI11: CEMMTH | AJ11: CEMLTH | AK11: CEMHET | AM11: =+B11 -> I-CEM-DRR-COA-ETS_E0 | AN11: =+AM11 -> I-CEM-DRR-COA-ETS_E0 | AO11: =+AN11 -> I-CEM-DRR-COA-ETS_E0 | AP11: =+AO11 -> I-CEM-DRR-COA-ETS_E0
B12: ="I-"&VLOOKUP(Y12,$AE$6:$AF$71,2,FALSE)&"-"&VLOOKUP(AA12,$AE$6:$AF$71,2,FALSE)&"-"&VLOOKUP(AB12,$AE$6:$AF$71,2,FALSE)&"-"&VLOOKUP(Z12,$AE$6:$AF$71,2,FALSE)&"_E0" -> I-CEM-KLN-OIL-ETS_E0 | C12: =_xlfn.TEXTJOIN(" - ",TRUE,X12,Y12,AA12,AB12,Z12) -> Industry - Cement - Cement/Lime Kiln - Oil - ETS | D12: =VLOOKUP(AB12,$AE$64:$AG$69,3,FALSE) -> INDOIL | E12: =VLOOKUP(Y12,$AE$6:$AF$71,2,FALSE)&"HTH,"&VLOOKUP(Y12,$AE$6:$AF$71,2,FALSE)&"MTH,"&VLOOKUP(Y12,$AE$6:$AF$71,2,FALSE)&"LTH,"&VLOOKUP(Y12,$AE$6:$AF$71,2,FALSE)&"HET" -> CEMHTH,CEMMTH,CEMLTH,CEMHET | F12: =+NRG_shares!V10 -> 0.9 | G12: 25 | H12: =IF(P12/I12/J12*1.075<0.001,0,P12/I12/J12*1.075) -> 0.0030142186 | I12: 31.536 | J12: 0.9 | K12: =+SUMIFS(NRG_shares!W$113:W$141,NRG_shares!$T$113:$T$141,Techs!$Y12,NRG_shares!$U$113:$U$141,Techs!$AA12) -> 1 | L12: =+SUMIFS(NRG_shares!X$113:X$141,NRG_shares!$T$113:$T$141,Techs!$Y12,NRG_shares!$U$113:$U$141,Techs!$AA12) -> 0 | M12: =+SUMIFS(NRG_shares!Y$113:Y$141,NRG_shares!$T$113:$T$141,Techs!$Y12,NRG_shares!$U$113:$U$141,Techs!$AA12) -> 0 | N12: =+SUMIFS(NRG_shares!Z$113:Z$141,NRG_shares!$T$113:$T$141,Techs!$Y12,NRG_shares!$U$113:$U$141,Techs!$AA12) -> 0 | O12: 3 | P12: =NRG_shares!J10*NRG_shares!O10*Conversions!$B$3 -> 0.0795821 | R12: I-CEM-DRR-NWS-ETS_E0 | S12: Share-O | T12: CEMLTH | U12: 0 | V12: 3 | X12: Industry | Y12: Cement | Z12: ETS | AA12: Cement/Lime Kiln | AB12: Oil | AE12: Food and Drink | AF12: FAP | AH12: CEMHTH | AI12: CEMMTH | AJ12: CEMLTH | AK12: CEMHET | AM12: =+B12 -> I-CEM-KLN-OIL-ETS_E0 | AN12: =+AM12 -> I-CEM-KLN-OIL-ETS_E0 | AO12: =+AN12 -> I-CEM-KLN-OIL-ETS_E0 | AP12: =+AO12 -> I-CEM-KLN-OIL-ETS_E0
B13: ="I-"&VLOOKUP(Y13,$AE$6:$AF$71,2,FALSE)&"-"&VLOOKUP(AA13,$AE$6:$AF$71,2,FALSE)&"-"&VLOOKUP(AB13,$AE$6:$AF$71,2,FALSE)&"-"&VLOOKUP(Z13,$AE$6:$AF$71,2,FALSE)&"_E0" -> I-CEM-DRR-OIL-ETS_E0 | C13: =_xlfn.TEXTJOIN(" - ",TRUE,X13,Y13,AA13,AB13,Z13) -> Industry - Cement - Dryer - Oil - ETS | D13: =VLOOKUP(AB13,$AE$64:$AG$69,3,FALSE) -> INDOIL | E13: =VLOOKUP(Y13,$AE$6:$AF$71,2,FALSE)&"HTH,"&VLOOKUP(Y13,$AE$6:$AF$71,2,FALSE)&"MTH,"&VLOOKUP(Y13,$AE$6:$AF$71,2,FALSE)&"LTH,"&VLOOKUP(Y13,$AE$6:$AF$71,2,FALSE)&"HET" -> CEMHTH,CEMMTH,CEMLTH,CEMHET | F13: =+NRG_shares!V11 -> 0.92 | G13: 25 | H13: =IF(P13/I13/J13*1.075<0.001,0,P13/I13/J13*1.075) -> 0 | I13: 31.536 | J13: 0.9 | K13: =+SUMIFS(NRG_shares!W$113:W$141,NRG_shares!$T$113:$T$141,Techs!$Y13,NRG_shares!$U$113:$U$141,Techs!$AA13) -> 0 | L13: =+SUMIFS(NRG_shares!X$113:X$141,NRG_shares!$T$113:$T$141,Techs!$Y13,NRG_shares!$U$113:$U$141,Techs!$AA13) -> 1 | M13: =+SUMIFS(NRG_shares!Y$113:Y$141,NRG_shares!$T$113:$T$141,Techs!$Y13,NRG_shares!$U$113:$U$141,Techs!$AA13) -> 0 | N13: =+SUMIFS(NRG_shares!Z$113:Z$141,NRG_shares!$T$113:$T$141,Techs!$Y13,NRG_shares!$U$113:$U$141,Techs!$AA13) -> 0 | O13: 3 | P13: =NRG_shares!J11*NRG_shares!O11*Conversions!$B$3 -> 0.0025159977 | R13: I-CEM-DRR-NWS-ETS_E0 | S13: Share-O | T13: CEMHET | U13: 0 | V13: 3 | X13: Industry | Y13: Cement | Z13: ETS | AA13: Dryer | AB13: Oil | AE13: Food and Drink | AF13: FAP | AH13: CEMHTH | AI13: CEMMTH | AJ13: CEMLTH | AK13: CEMHET | AM13: =+B13 -> I-CEM-DRR-OIL-ETS_E0 | AN13: =+AM13 -> I-CEM-DRR-OIL-ETS_E0 | AO13: =+AN13 -> I-CEM-DRR-OIL-ETS_E0 | AP13: =+AO13 -> I-CEM-DRR-OIL-ETS_E0
B14: ="I-"&VLOOKUP(Y14,$AE$6:$AF$71,2,FALSE)&"-"&VLOOKUP(AA14,$AE$6:$AF$71,2,FALSE)&"-"&VLOOKUP(AB14,$AE$6:$AF$71,2,FALSE)&"-"&VLOOKUP(Z14,$AE$6:$AF$71,2,FALSE)&"_E0" -> I-CEM-KLN-GAS-ETS_E0 | C14: =_xlfn.TEXTJOIN(" - ",TRUE,X14,Y14,AA14,AB14,Z14) -> Industry - Cement - Cement/Lime Kiln - Gas - ETS | D14: =VLOOKUP(AB14,$AE$64:$AG$69,3,FALSE) -> INDGAS | E14: =VLOOKUP(Y14,$AE$6:$AF$71,2,FALSE)&"HTH,"&VLOOKUP(Y14,$AE$6:$AF$71,2,FALSE)&"MTH,"&VLOOKUP(Y14,$AE$6:$AF$71,2,FALSE)&"LTH,"&VLOOKUP(Y14,$AE$6:$AF$71,2,FALSE)&"HET" -> CEMHTH,CEMMTH,CEMLTH,CEMHET | F14: =+NRG_shares!V12 -> 0.9 | G14: 25 | H14: =IF(P14/I14/J14*1.075<0.001,0,P14/I14/J14*1.075) -> 0 | I14: 31.536 | J14: 0.9 | K14: =+SUMIFS(NRG_shares!W$113:W$141,NRG_shares!$T$113:$T$141,Techs!$Y14,NRG_shares!$U$113:$U$141,Techs!$AA14) -> 1 | L14: =+SUMIFS(NRG_shares!X$113:X$141,NRG_shares!$T$113:$T$141,Techs!$Y14,NRG_shares!$U$113:$U$141,Techs!$AA14) -> 0 | M14: =+SUMIFS(NRG_shares!Y$113:Y$141,NRG_shares!$T$113:$T$141,Techs!$Y14,NRG_shares!$U$113:$U$141,Techs!$AA14) -> 0 | N14: =+SUMIFS(NRG_shares!Z$113:Z$141,NRG_shares!$T$113:$T$141,Techs!$Y14,NRG_shares!$U$113:$U$141,Techs!$AA14) -> 0 | O14: 3 | P14: =NRG_shares!J12*NRG_shares!O12*Conversions!$B$3 -> 0.00033826814 | R14: I-CEM-KLN-RWS-ETS_E0 | S14: Share-O | T14: CEMHTH | U14: 1 | V14: 3 | X14: Industry | Y14: Cement | Z14: ETS | AA14: Cement/Lime Kiln | AB14: Gas | AE14: Food and Drink | AF14: FAP | AH14: CEMHTH | AI14: CEMMTH | AJ14: CEMLTH | AK14: CEMHET | AM14: =+B14 -> I-CEM-KLN-GAS-ETS_E0 | AN14: =+AM14 -> I-CEM-KLN-GAS-ETS_E0 | AO14: =+AN14 -> I-CEM-KLN-GAS-ETS_E0 | AP14: =+AO14 -> I-CEM-KLN-GAS-ETS_E0
B15: ="I-"&VLOOKUP(Y15,$AE$6:$AF$71,2,FALSE)&"-"&VLOOKUP(AA15,$AE$6:$AF$71,2,FALSE)&"-"&VLOOKUP(AB15,$AE$6:$AF$71,2,FALSE)&"-"&VLOOKUP(Z15,$AE$6:$AF$71,2,FALSE)&"_E0" -> I-CEM-DRR-GAS-ETS_E0 | C15: =_xlfn.TEXTJOIN(" - ",TRUE,X15,Y15,AA15,AB15,Z15) -> Industry - Cement - Dryer - Gas - ETS | D15: =VLOOKUP(AB15,$AE$64:$AG$69,3,FALSE) -> INDGAS | E15: =VLOOKUP(Y15,$AE$6:$AF$71,2,FALSE)&"HTH,"&VLOOKUP(Y15,$AE$6:$AF$71,2,FALSE)&"MTH,"&VLOOKUP(Y15,$AE$6:$AF$71,2,FALSE)&"LTH,"&VLOOKUP(Y15,$AE$6:$AF$71,2,FALSE)&"HET" -> CEMHTH,CEMMTH,CEMLTH,CEMHET | F15: =+NRG_shares!V13 -> 0.92 | G15: 25 | H15: =IF(P15/I15/J15*1.075<0.001,0,P15/I15/J15*1.075) -> 0 | I15: 31.536 | J15: 0.9 | K15: =+SUMIFS(NRG_shares!W$113:W$141,NRG_shares!$T$113:$T$141,Techs!$Y15,NRG_shares!$U$113:$U$141,Techs!$AA15) -> 0 | L15: =+SUMIFS(NRG_shares!X$113:X$141,NRG_shares!$T$113:$T$141,Techs!$Y15,NRG_shares!$U$113:$U$141,Techs!$AA15) -> 1 | M15: =+SUMIFS(NRG_shares!Y$113:Y$141,NRG_shares!$T$113:$T$141,Techs!$Y15,NRG_shares!$U$113:$U$141,Techs!$AA15) -> 0 | N15: =+SUMIFS(NRG_shares!Z$113:Z$141,NRG_shares!$T$113:$T$141,Techs!$Y15,NRG_shares!$U$113:$U$141,Techs!$AA15) -> 0 | O15: 3 | P15: =NRG_shares!J13*NRG_shares!O13*Conversions!$B$3 -> 1.0694388e-05 | R15: I-CEM-KLN-RWS-ETS_E0 | S15: Share-O | T15: CEMMTH | U15: 0 | V15: 3 | X15: Industry | Y15: Cement | Z15: ETS | AA15: Dryer | AB15: Gas | AE15: Food and Drink | AF15: FAP | AH15: CEMHTH | AI15: CEMMTH | AJ15: CEMLTH | AK15: CEMHET | AM15: =+B15 -> I-CEM-DRR-GAS-ETS_E0 | AN15: =+AM15 -> I-CEM-DRR-GAS-ETS_E0 | AO15: =+AN15 -> I-CEM-DRR-GAS-ETS_E0 | AP15: =+AO15 -> I-CEM-DRR-GAS-ETS_E0
B16: ="I-"&VLOOKUP(Y16,$AE$6:$AF$71,2,FALSE)&"-"&VLOOKUP(AA16,$AE$6:$AF$71,2,FALSE)&"-"&VLOOKUP(AB16,$AE$6:$AF$71,2,FALSE)&"-"&VLOOKUP(Z16,$AE$6:$AF$71,2,FALSE)&"_E0" -> I-CAF-BLR-OIL-ETS_E0 | C16: =_xlfn.TEXTJOIN(" - ",TRUE,X16,Y16,AA16,AB16,Z16) -> Industry - Chemicals - Boiler - Oil - ETS | D16: =VLOOKUP(AB16,$AE$64:$AG$69,3,FALSE) -> INDOIL | E16: =VLOOKUP(Y16,$AE$6:$AF$71,2,FALSE)&"HTH,"&VLOOKUP(Y16,$AE$6:$AF$71,2,FALSE)&"MTH,"&VLOOKUP(Y16,$AE$6:$AF$71,2,FALSE)&"LTH,"&VLOOKUP(Y16,$AE$6:$AF$71,2,FALSE)&"HET" -> CAFHTH,CAFMTH,CAFLTH,CAFHET | F16: =+NRG_shares!V14 -> 0.92 | G16: 25 | H16: =IF(P16/I16/J16*1.075<0.001,0,P16/I16/J16*1.075) -> 0.0041962447 | I16: 31.536 | J16: 0.9 | K16: =+SUMIFS(NRG_shares!W$113:W$141,NRG_shares!$T$113:$T$141,Techs!$Y16,NRG_shares!$U$113:$U$141,Techs!$AA16) -> 0 | L16: =+SUMIFS(NRG_shares!X$113:X$141,NRG_shares!$T$113:$T$141,Techs!$Y16,NRG_shares!$U$113:$U$141,Techs!$AA16) -> 0.1 | M16: =+SUMIFS(NRG_shares!Y$113:Y$141,NRG_shares!$T$113:$T$141,Techs!$Y16,NRG_shares!$U$113:$U$141,Techs!$AA16) -> 0.7 | N16: =+SUMIFS(NRG_shares!Z$113:Z$141,NRG_shares!$T$113:$T$141,Techs!$Y16,NRG_shares!$U$113:$U$141,Techs!$AA16) -> 0.2 | O16: 3 | P16: =NRG_shares!J14*NRG_shares!O14*Conversions!$B$3 -> 0.11079023 | R16: I-CEM-KLN-RWS-ETS_E0 | S16: Share-O | T16: CEMLTH | U16: 0 | V16: 3 | X16: Industry | Y16: Chemicals | Z16: ETS | AA16: Boiler | AB16: Oil | AE16: Lime | AF16: LIM | AH16: CAFHTH | AI16: CAFMTH | AJ16: CAFLTH | AK16: CAFHET | AM16: =+B16 -> I-CAF-BLR-OIL-ETS_E0 | AN16: =+AM16 -> I-CAF-BLR-OIL-ETS_E0 | AO16: =+AN16 -> I-CAF-BLR-OIL-ETS_E0 | AP16: =+AO16 -> I-CAF-BLR-OIL-ETS_E0
B17: ="I-"&VLOOKUP(Y17,$AE$6:$AF$71,2,FALSE)&"-"&VLOOKUP(AA17,$AE$6:$AF$71,2,FALSE)&"-"&VLOOKUP(AB17,$AE$6:$AF$71,2,FALSE)&"-"&VLOOKUP(Z17,$AE$6:$AF$71,2,FALSE)&"_E0" -> I-CAF-CHP-OIL-ETS_E0 | C17: =_xlfn.TEXTJOIN(" - ",TRUE,X17,Y17,AA17,AB17,Z17) -> Industry - Chemicals - CHP - Oil - ETS | D17: =VLOOKUP(AB17,$AE$64:$AG$69,3,FALSE) -> INDOIL | E17: =VLOOKUP(Y17,$AE$6:$AF$71,2,FALSE)&"HTH,"&VLOOKUP(Y17,$AE$6:$AF$71,2,FALSE)&"MTH,"&VLOOKUP(Y17,$AE$6:$AF$71,2,FALSE)&"LTH,"&VLOOKUP(Y17,$AE$6:$AF$71,2,FALSE)&"HET" -> CAFHTH,CAFMTH,CAFLTH,CAFHET | F17: =+NRG_shares!V15 -> 0.5 | G17: 25 | H17: =IF(P17/I17/J17*1.075<0.001,0,P17/I17/J17*1.075) -> 0.0025339642 | I17: 31.536 | J17: 0.9 | K17: =+SUMIFS(NRG_shares!W$113:W$141,NRG_shares!$T$113:$T$141,Techs!$Y17,NRG_shares!$U$113:$U$141,Techs!$AA17) -> 0 | L17: =+SUMIFS(NRG_shares!X$113:X$141,NRG_shares!$T$113:$T$141,Techs!$Y17,NRG_shares!$U$113:$U$141,Techs!$AA17) -> 1 | M17: =+SUMIFS(NRG_shares!Y$113:Y$141,NRG_shares!$T$113:$T$141,Techs!$Y17,NRG_shares!$U$113:$U$141,Techs!$AA17) -> 0 | N17: =+SUMIFS(NRG_shares!Z$113:Z$141,NRG_shares!$T$113:$T$141,Techs!$Y17,NRG_shares!$U$113:$U$141,Techs!$AA17) -> 0 | O17: 3 | P17: =NRG_shares!J15*NRG_shares!O15*Conversions!$B$3 -> 0.066902311 | R17: I-CEM-KLN-RWS-ETS_E0 | S17: Share-O | T17: CEMHET | U17: 0 | V17: 3 | X17: Industry | Y17: Chemicals | Z17: ETS | AA17: CHP | AB17: Oil | AE17: Lime | AF17: LIM | AH17: CAFHTH | AI17: CAFMTH | AJ17: CAFLTH | AK17: CAFHET | AM17: =+B17 -> I-CAF-CHP-OIL-ETS_E0 | AN17: =+AM17 -> I-CAF-CHP-OIL-ETS_E0 | AO17: =+AN17 -> I-CAF-CHP-OIL-ETS_E0 | AP17: =+AO17 -> I-CAF-CHP-OIL-ETS_E0
B18: ="I-"&VLOOKUP(Y18,$AE$6:$AF$71,2,FALSE)&"-"&VLOOKUP(AA18,$AE$6:$AF$71,2,FALSE)&"-"&VLOOKUP(AB18,$AE$6:$AF$71,2,FALSE)&"-"&VLOOKUP(Z18,$AE$6:$AF$71,2,FALSE)&"_E0" -> I-CAF-OVN-OIL-ETS_E0 | C18: =_xlfn.TEXTJOIN(" - ",TRUE,X18,Y18,AA18,AB18,Z18) -> Industry - Chemicals - Oven - Oil - ETS | D18: =VLOOKUP(AB18,$AE$64:$AG$69,3,FALSE) -> INDOIL | E18: =VLOOKUP(Y18,$AE$6:$AF$71,2,FALSE)&"HTH,"&VLOOKUP(Y18,$AE$6:$AF$71,2,FALSE)&"MTH,"&VLOOKUP(Y18,$AE$6:$AF$71,2,FALSE)&"LTH,"&VLOOKUP(Y18,$AE$6:$AF$71,2,FALSE)&"HET" -> CAFHTH,CAFMTH,CAFLTH,CAFHET | F18: =+NRG_shares!V16 -> 0.92 | G18: 25 | H18: =IF(P18/I18/J18*1.075<0.001,0,P18/I18/J18*1.075) -> 0 | I18: 31.536 | J18: 0.9 | K18: =+SUMIFS(NRG_shares!W$113:W$141,NRG_shares!$T$113:$T$141,Techs!$Y18,NRG_shares!$U$113:$U$141,Techs!$AA18) -> 0 | L18: =+SUMIFS(NRG_shares!X$113:X$141,NRG_shares!$T$113:$T$141,Techs!$Y18,NRG_shares!$U$113:$U$141,Techs!$AA18) -> 0 | M18: =+SUMIFS(NRG_shares!Y$113:Y$141,NRG_shares!$T$113:$T$141,Techs!$Y18,NRG_shares!$U$113:$U$141,Techs!$AA18) -> 1 | N18: =+SUMIFS(NRG_shares!Z$113:Z$141,NRG_shares!$T$113:$T$141,Techs!$Y18,NRG_shares!$U$113:$U$141,Techs!$AA18) -> 0 | O18: 3 | P18: =NRG_shares!J16*NRG_shares!O16*Conversions!$B$3 -> 0.012310025 | R18: I-CEM-DRR-RWS-ETS_E0 | S18: Share-O | T18: CEMHTH | U18: 0 | V18: 3 | X18: Industry | Y18: Chemicals | Z18: ETS | AA18: Oven | AB18: Oil | AE18: Lime | AF18: LIM | AH18: CAFHTH | AI18: CAFMTH | AJ18: CAFLTH | AK18: CAFHET | AM18: =+B18 -> I-CAF-OVN-OIL-ETS_E0 | AN18: =+AM18 -> I-CAF-OVN-OIL-ETS_E0 | AO18: =+AN18 -> I-CAF-OVN-OIL-ETS_E0 | AP18: =+AO18 -> I-CAF-OVN-OIL-ETS_E0
... B63: ="I-"&VLOOKUP(Y63,$AE$6:$AF$71,2,FALSE)&"-"&VLOOKUP(AA63,$AE$6:$AF$71,2,FALSE)&"-"&VLOOKUP(AB63,$AE$6:$AF$71,2,FALSE)&"-"&VLOOKUP(Z63,$AE$6:$AF$71,2,FALSE)&"_E0" -> I-LIM-FRN-GAS-ETS_E0 | C63: =_xlfn.TEXTJOIN(" - ",TRUE,X63,Y63,AA63,AB63,Z63) -> Industry - Lime - Furnace - Gas - ETS | D63: =VLOOKUP(AB63,$AE$64:$AG$69,3,FALSE) -> INDGAS | E63: =VLOOKUP(Y63,$AE$6:$AF$71,2,FALSE)&"HTH,"&VLOOKUP(Y63,$AE$6:$AF$71,2,FALSE)&"MTH,"&VLOOKUP(Y63,$AE$6:$AF$71,2,FALSE)&"LTH,"&VLOOKUP(Y63,$AE$6:$AF$71,2,FALSE)&"HET" -> LIMHTH,LIMMTH,LIMLTH,LIMHET | F63: =+NRG_shares!V61 -> 0.85 | G63: 25 | H63: =IF(P63/I63/J63*1.075<0.001,0,P63/I63/J63*1.075) -> 0.00521039 | I63: 31.536 | J63: 0.9 | K63: =+SUMIFS(NRG_shares!W$113:W$141,NRG_shares!$T$113:$T$141,Techs!$Y63,NRG_shares!$U$113:$U$141,Techs!$AA63) -> 1 | L63: =+SUMIFS(NRG_shares!X$113:X$141,NRG_shares!$T$113:$T$141,Techs!$Y63,NRG_shares!$U$113:$U$141,Techs!$AA63) -> 0 | M63: =+SUMIFS(NRG_shares!Y$113:Y$141,NRG_shares!$T$113:$T$141,Techs!$Y63,NRG_shares!$U$113:$U$141,Techs!$AA63) -> 0 | N63: =+SUMIFS(NRG_shares!Z$113:Z$141,NRG_shares!$T$113:$T$141,Techs!$Y63,NRG_shares!$U$113:$U$141,Techs!$AA63) -> 0 | O63: 3 | P63: =NRG_shares!J61*NRG_shares!O61*Conversions!$B$3 -> 0.13756593 | R63: I-CAF-CHP-GAS-ETS_E0 | S63: Share-O | T63: CAFMTH | U63: 1 | V63: 3 | X63: Industry | Y63: Lime | Z63: ETS | AA63: Furnace | AB63: Gas | AE63: Boiler | AF63: BLR | AH63: LIMHTH | AI63: LIMMTH | AJ63: LIMLTH | AK63: LIMHET | AM63: =+B63 -> I-LIM-FRN-GAS-ETS_E0 | AN63: =+AM63 -> I-LIM-FRN-GAS-ETS_E0 | AO63: =+AN63 -> I-LIM-FRN-GAS-ETS_E0 | AP63: =+AO63 -> I-LIM-FRN-GAS-ETS_E0
B64: ="I-"&VLOOKUP(Y64,$AE$6:$AF$71,2,FALSE)&"-"&VLOOKUP(AA64,$AE$6:$AF$71,2,FALSE)&"-"&VLOOKUP(AB64,$AE$6:$AF$71,2,FALSE)&"-"&VLOOKUP(Z64,$AE$6:$AF$71,2,FALSE)&"_E0" -> I-MAP-CHP-OIL-ETS_E0 | C64: =_xlfn.TEXTJOIN(" - ",TRUE,X64,Y64,AA64,AB64,Z64) -> Industry - Metals - CHP - Oil - ETS | D64: =VLOOKUP(AB64,$AE$64:$AG$69,3,FALSE) -> INDOIL | E64: =VLOOKUP(Y64,$AE$6:$AF$71,2,FALSE)&"HTH,"&VLOOKUP(Y64,$AE$6:$AF$71,2,FALSE)&"MTH,"&VLOOKUP(Y64,$AE$6:$AF$71,2,FALSE)&"LTH,"&VLOOKUP(Y64,$AE$6:$AF$71,2,FALSE)&"HET" -> MAPHTH,MAPMTH,MAPLTH,MAPHET | F64: =+NRG_shares!V62 -> 0.5 | G64: 25 | H64: =IF(P64/I64/J64*1.075<0.001,0,P64/I64/J64*1.075) -> 0.0016612376 | I64: 31.536 | J64: 0.9 | K64: =+SUMIFS(NRG_shares!W$113:W$141,NRG_shares!$T$113:$T$141,Techs!$Y64,NRG_shares!$U$113:$U$141,Techs!$AA64) -> 0 | L64: =+SUMIFS(NRG_shares!X$113:X$141,NRG_shares!$T$113:$T$141,Techs!$Y64,NRG_shares!$U$113:$U$141,Techs!$AA64) -> 1 | M64: =+SUMIFS(NRG_shares!Y$113:Y$141,NRG_shares!$T$113:$T$141,Techs!$Y64,NRG_shares!$U$113:$U$141,Techs!$AA64) -> 0 | N64: =+SUMIFS(NRG_shares!Z$113:Z$141,NRG_shares!$T$113:$T$141,Techs!$Y64,NRG_shares!$U$113:$U$141,Techs!$AA64) -> 0 | O64: 3 | P64: =NRG_shares!J62*NRG_shares!O62*Conversions!$B$3 -> 0.043860381 | R64: I-CAF-CHP-GAS-ETS_E0 | S64: Share-O | T64: CAFLTH | U64: 0 | V64: 3 | X64: Industry | Y64: Metals | Z64: ETS | AA64: CHP | AB64: Oil | AE64: Non-bio waste | AF64: NWS | AG64: INDNWS | AH64: MAPHTH | AI64: MAPMTH | AJ64: MAPLTH | AK64: MAPHET | AM64: =+B64 -> I-MAP-CHP-OIL-ETS_E0 | AN64: =+AM64 -> I-MAP-CHP-OIL-ETS_E0 | AO64: =+AN64 -> I-MAP-CHP-OIL-ETS_E0 | AP64: =+AO64 -> I-MAP-CHP-OIL-ETS_E0
